Workbook

Sheet MasterData
A1: ⚙ MASTER DATA — Add new entries at the bottom of any column.
A2: 💡 To add a new client: add next ID (CLI-XXX) in col A and name in col B. All other lists: just add below the last entry.
A3: Client ID | B3: Client Name | C3: Roles | D3: Departments | E3: Cities | F3: Seniority | G3: Pipeline Stages | H3: Position Status | I3: Recruiters
A4: CLI-001 | B4: ABNAH | C4: ARM | D4: F&B - Kitchen | E4: Mumbai | F4: Trainee | G4: Sent to Client | H4: Open | I4: Edwin
A5: CLI-002 | B5: Abhinav Immigration | C5: Assistant Bartender | D5: F&B - Service | E5: Delhi | F5: Junior | G5: Interview Scheduled | H5: On Hold | I5: Manokamna
A6: CLI-003 | B6: Adarsh Sweets | C6: Assistant Front Office Manager | D6: Bar & Beverages | E6: Bangalore | F6: Mid | G6: Result Awaited | H6: Closed - Filled | I6: Hardik
A7: CLI-004 | B7: Agarwal Biryani | C7: Assistant Manager | D7: Front Office & Rooms | E7: Hyderabad | F7: Senior | G7: Selected | H7: Closed - Cancelled | I7: Mohit
A8: CLI-005 | B8: All in | C8: Assistant Outlet Manager | D8: Housekeeping | E8: Pune | F8: Leadership | G8: Rejected | I8: Aakash
A9: CLI-006 | B9: Aria Communication | C9: Assistant Stores Manager | D9: HR & Training | E9: Goa | G9: Hold
A10: CLI-007 | B10: Atmosphere | C10: Asst Cafe Manager | D10: Marketing & PR | E10: Chennai | G10: Offer Sent
A11: CLI-008 | B11: August Café | C11: Bar Lead | D11: Sales & Revenue | E11: Kolkata | G11: Offer Accepted
A12: CLI-009 | B12: Aures hospitality | C12: Bar Manager | D12: Finance & Accounts | E12: Ahmedabad | G12: Joined
A13: CLI-010 | B13: BB | C13: Bar Supervisor | D13: Operations | E13: Jaipur | G13: Candidate Dropped
A14: CLI-011 | B14: BTC | C14: Barback | D14: Store & Purchase | E14: Other
A15: CLI-012 | B15: Baesic Fit | C15: Barista | D15: Tech & Data
A16: CLI-013 | B16: Bare | C16: Barista Head | D16: Other
A17: CLI-014 | B17: Blondie | C17: Barista Trainer
A18: CLI-015 | B18: Circa 11 | C18: Bartender
A19: CLI-016 | B19: CocoCart | C19: CDP
A20: CLI-017 | B20: DU Hospitality | C20: CRM
A21: CLI-018 | B21: Diva | C21: Cafe Manager
A22: CLI-019 | B22: Donmai | C22: Cafe Supervisor
A23: CLI-020 | B23: Doppler | C23: Captain
A24: CLI-021 | B24: Dough and Joe | C24: Cashier
A25: CLI-022 | B25: EDD | C25: Chef
A26: CLI-023 | B26: FHPL | C26: Commi
A27: CLI-024 | B27: Flavour Pots | C27: Commi 1
A28: CLI-025 | B28: Food Square | C28: Commi 2
... A81: CLI-078 | B81: Niko | C81: Senior Barista
B82: Courtside | C82: Senior Bartender
B83: Penang Table | C83: Senior CDP
B84: TGC | C84: Senior Captain
B85: Corleone's | C85: Senior GRE
B86: Nenapu | C86: Senior Sous Chef
C87: Senior Steward
C88: Social Media Manager
C89: Sommelier
C90: Sous Chef
C91: Sr. Duty Manager
C92: Steward
...

Sheet Open Positions
A1: 🏨 OPEN POSITIONS
A2: 💡 Select Client Name → Position ID, Client ID, Filled and Remaining populate automatically. Teal columns are auto — do not edit.
A3: Position ID | B3: Client Name | C3: Role | D3: Department | E3: City | F3: Seniority | G3: Date Opened | H3: Target Close | I3: Assigned To | J3: No. of Openings | K3: Status | L3: Remarks | M3: Client ID | N3: Filled | O3: Remaining
A4: CLI-031-POS-001 | B4: Hunger Inc | C4: Cafe Steward | D4: F&B - Service | E4: Mumbai | F4: Junior | I4: Edwin | J4: 7 | K4: Open | M4: CLI-031 | N4: 3 | O4: =IF(J4="","",J4-N4) -> 4 | Q4: =IFERROR(MasterData!$B4,"") -> ABNAH | R4: =IFERROR(MasterData!$C4,"") -> ARM | S4: =IFERROR(MasterData!$D4,"") -> F&B - Kitchen | T4: =IFERROR(MasterData!$E4,"") -> Mumbai | U4: =IFERROR(MasterData!$F4,"") -> Trainee | V4: =IFERROR(MasterData!$I4,"") -> Edwin | W4: =IFERROR(MasterData!$H4,"") -> Open
A5: CLI-031-POS-002 | B5: Hunger Inc | C5: Captain | D5: F&B - Service | E5: Mumbai | F5: Junior | I5: Edwin | J5: 7 | K5: Open | M5: CLI-031 | N5: 0 | O5: =IF(J5="","",J5-N5) -> 7 | Q5: =IFERROR(MasterData!$B5,"") -> Abhinav Immigration | R5: =IFERROR(MasterData!$C5,"") -> Assistant Bartender | S5: =IFERROR(MasterData!$D5,"") -> F&B - Service | T5: =IFERROR(MasterData!$E5,"") -> Delhi | U5: =IFERROR(MasterData!$F5,"") -> Junior | V5: =IFERROR(MasterData!$I5,"") -> Manokamna | W5: =IFERROR(MasterData!$H5,"") -> On Hold
A6: CLI-026-POS-001 | B6: Foodmatters | C6: Captain | D6: F&B - Service | E6: Mumbai | F6: Junior | I6: Edwin | J6: 0 | K6: Closed | M6: CLI-026 | N6: 0 | O6: =IF(J6="","",J6-N6) -> 0 | Q6: =IFERROR(MasterData!$B6,"") -> Adarsh Sweets | R6: =IFERROR(MasterData!$C6,"") -> Assistant Front Office Manager | S6: =IFERROR(MasterData!$D6,"") -> Bar & Beverages | T6: =IFERROR(MasterData!$E6,"") -> Bangalore | U6: =IFERROR(MasterData!$F6,"") -> Mid | V6: =IFERROR(MasterData!$I6,"") -> Hardik | W6: =IFERROR(MasterData!$H6,"") -> Closed - Filled
A7: CLI-026-POS-002 | B7: Foodmatters | C7: Steward | D7: F&B - Service | E7: Mumbai | F7: Junior | I7: Edwin | J7: 8 | K7: Open | M7: CLI-026 | N7: 0 | O7: =IF(J7="","",J7-N7) -> 8 | Q7: =IFERROR(MasterData!$B7,"") -> Agarwal Biryani | R7: =IFERROR(MasterData!$C7,"") -> Assistant Manager | S7: =IFERROR(MasterData!$D7,"") -> Front Office & Rooms | T7: =IFERROR(MasterData!$E7,"") -> Hyderabad | U7: =IFERROR(MasterData!$F7,"") -> Senior | V7: =IFERROR(MasterData!$I7,"") -> Mohit | W7: =IFERROR(MasterData!$H7,"") -> Closed - Cancelled
A8: CLI-026-POS-003 | B8: Foodmatters | C8: Bartender | D8: F&B - Service | E8: Mumbai | F8: Junior | I8: Edwin | J8: 0 | K8: Closed | M8: CLI-026 | N8: 0 | O8: =IF(J8="","",J8-N8) -> 0 | Q8: =IFERROR(MasterData!$B8,"") -> All in | R8: =IFERROR(MasterData!$C8,"") -> Assistant Outlet Manager | S8: =IFERROR(MasterData!$D8,"") -> Housekeeping | T8: =IFERROR(MasterData!$E8,"") -> Pune | U8: =IFERROR(MasterData!$F8,"") -> Leadership | V8: =IFERROR(MasterData!$I8,"") -> Aakash | W8: =IFERROR(MasterData!$H8,"")
A9: CLI-001-POS-001 | B9: ABNAH | C9: Steward | D9: F&B - Service | E9: Mumbai | F9: Junior | I9: Mohit | J9: 5 | K9: Open | M9: CLI-001 | N9: 0 | O9: =IF(J9="","",J9-N9) -> 5 | Q9: =IFERROR(MasterData!$B9,"") -> Aria Communication | R9: =IFERROR(MasterData!$C9,"") -> Assistant Stores Manager | S9: =IFERROR(MasterData!$D9,"") -> HR & Training | T9: =IFERROR(MasterData!$E9,"") -> Goa | U9: =IFERROR(MasterData!$F9,"") | V9: =IFERROR(MasterData!$I9,"") | W9: =IFERROR(MasterData!$H9,"")
A10: CLI-001-POS-002 | B10: ABNAH | C10: GRE | D10: F&B - Service | E10: Mumbai | F10: Junior | I10: Mohit | J10: 3 | K10: Open | M10: CLI-001 | N10: 0 | O10: =IF(J10="","",J10-N10) -> 3 | Q10: =IFERROR(MasterData!$B10,"") -> Atmosphere | R10: =IFERROR(MasterData!$C10,"") -> Asst Cafe Manager | S10: =IFERROR(MasterData!$D10,"") -> Marketing & PR | T10: =IFERROR(MasterData!$E10,"") -> Chennai | U10: =IFERROR(MasterData!$F10,"") | V10: =IFERROR(MasterData!$I10,"") | W10: =IFERROR(MasterData!$H10,"")
A11: CLI-001-POS-003 | B11: ABNAH | C11: Bartender | D11: F&B - Service | E11: Mumbai | F11: Junior | I11: Mohit | J11: 3 | K11: Open | M11: CLI-001 | N11: 0 | O11: =IF(J11="","",J11-N11) -> 3 | Q11: =IFERROR(MasterData!$B11,"") -> August Café | R11: =IFERROR(MasterData!$C11,"") -> Bar Lead | S11: =IFERROR(MasterData!$D11,"") -> Sales & Revenue | T11: =IFERROR(MasterData!$E11,"") -> Kolkata | U11: =IFERROR(MasterData!$F11,"") | V11: =IFERROR(MasterData!$I11,"") | W11: =IFERROR(MasterData!$H11,"")
A12: CLI-014-POS-001 | B12: Blondie | C12: ARM | D12: F&B - Service | E12: Mumbai | F12: Mid | I12: Aakash | J12: 3 | K12: Open | M12: CLI-014 | N12: 0 | O12: =IF(J12="","",J12-N12) -> 3 | Q12: =IFERROR(MasterData!$B12,"") -> Aures hospitality | R12: =IFERROR(MasterData!$C12,"") -> Bar Manager | S12: =IFERROR(MasterData!$D12,"") -> Finance & Accounts | T12: =IFERROR(MasterData!$E12,"") -> Ahmedabad | U12: =IFERROR(MasterData!$F12,"") | V12: =IFERROR(MasterData!$I12,"") | W12: =IFERROR(MasterData!$H12,"")
A13: CLI-014-POS-002 | B13: Blondie | C13: RM | D13: F&B - Service | E13: Mumbai | F13: Mid | I13: Aakash | J13: 3 | K13: Open | M13: CLI-014 | N13: 0 | O13: =IF(J13="","",J13-N13) -> 3 | Q13: =IFERROR(MasterData!$B13,"") -> BB | R13: =IFERROR(MasterData!$C13,"") -> Bar Supervisor | S13: =IFERROR(MasterData!$D13,"") -> Operations | T13: =IFERROR(MasterData!$E13,"") -> Jaipur | U13: =IFERROR(MasterData!$F13,"") | V13: =IFERROR(MasterData!$I13,"") | W13: =IFERROR(MasterData!$H13,"")
A14: CLI-014-POS-003 | B14: Blondie | C14: Operations Head | D14: Operations | E14: Mumbai | F14: Senior | I14: Aakash | J14: 1 | K14: Closed | M14: CLI-014 | N14: 0 | O14: =IF(J14="","",J14-N14) -> 1 | Q14: =IFERROR(MasterData!$B14,"") -> BTC | R14: =IFERROR(MasterData!$C14,"") -> Barback | S14: =IFERROR(MasterData!$D14,"") -> Store & Purchase | T14: =IFERROR(MasterData!$E14,"") -> Other | U14: =IFERROR(MasterData!$F14,"") | V14: =IFERROR(MasterData!$I14,"") | W14: =IFERROR(MasterData!$H14,"")
A15: CLI-014-POS-004 | B15: Blondie | C15: Social Media Manager | D15: Marketing & PR | E15: Mumbai | F15: Junior | I15: Aakash | J15: 2 | K15: Open | M15: CLI-014 | N15: 2 | O15: =IF(J15="","",J15-N15) -> 0 | Q15: =IFERROR(MasterData!$B15,"") -> Baesic Fit | R15: =IFERROR(MasterData!$C15,"") -> Barista | S15: =IFERROR(MasterData!$D15,"") -> Tech & Data | T15: =IFERROR(MasterData!$E15,"") | U15: =IFERROR(MasterData!$F15,"") | V15: =IFERROR(MasterData!$I15,"") | W15: =IFERROR(MasterData!$H15,"")
A16: CLI-016-POS-001 | B16: CocoCart | C16: F&B Associate | D16: F&B - Service | E16: Mumbai | F16: Junior | I16: Mohit | J16: 35 | K16: Open | M16: CLI-016 | N16: 0 | O16: =IF(J16="","",J16-N16) -> 35 | Q16: =IFERROR(MasterData!$B16,"") -> Bare | R16: =IFERROR(MasterData!$C16,"") -> Barista Head | S16: =IFERROR(MasterData!$D16,"") -> Other | T16: =IFERROR(MasterData!$E16,"") | U16: =IFERROR(MasterData!$F16,"") | V16: =IFERROR(MasterData!$I16,"") | W16: =IFERROR(MasterData!$H16,"")
A17: CLI-071-POS-001 | B17: UGIPL | C17: Sous Chef | D17: F&B - Kitchen | E17: Mumbai | F17: Senior | I17: Mohit | J17: 1 | K17: Open | L17: Pizza Chef | M17: CLI-071 | N17: 0 | O17: =IF(J17="","",J17-N17) -> 1 | Q17: =IFERROR(MasterData!$B17,"") -> Blondie | R17: =IFERROR(MasterData!$C17,"") -> Barista Trainer | S17: =IFERROR(MasterData!$D17,"") | T17: =IFERROR(MasterData!$E17,"") | U17: =IFERROR(MasterData!$F17,"") | V17: =IFERROR(MasterData!$I17,"") | W17: =IFERROR(MasterData!$H17,"")
A18: CLI-071-POS-002 | B18: UGIPL | C18: Outlet Supervisor | D18: F&B - Service | E18: Mumbai | F18: Mid | I18: Manokamna | J18: 3 | K18: Open | M18: CLI-071 | N18: 0 | O18: =IF(J18="","",J18-N18) -> 3 | Q18: =IFERROR(MasterData!$B18,"") -> Circa 11 | R18: =IFERROR(MasterData!$C18,"") -> Bartender | S18: =IFERROR(MasterData!$D18,"") | T18: =IFERROR(MasterData!$E18,"") | U18: =IFERROR(MasterData!$F18,"") | V18: =IFERROR(MasterData!$I18,"") | W18: =IFERROR(MasterData!$H18,"")
A19: CLI-071-POS-003 | B19: UGIPL | C19: Steward | D19: F&B - Service | E19: Mumbai | F19: Junior | I19: Manokamna | J19: 8 | K19: Open | M19: CLI-071 | N19: 0 | O19: =IF(J19="","",J19-N19) -> 8 | Q19: =IFERROR(MasterData!$B19,"") -> CocoCart | R19: =IFERROR(MasterData!$C19,"") -> CDP | S19: =IFERROR(MasterData!$D19,"") | T19: =IFERROR(MasterData!$E19,"") | U19: =IFERROR(MasterData!$F19,"") | V19: =IFERROR(MasterData!$I19,"") | W19: =IFERROR(MasterData!$H19,"")
A20: CLI-061-POS-001 | B20: Speciality | C20: RM | D20: F&B - Service | E20: Delhi | F20: Mid | I20: Hardik | J20: 2 | K20: Open | M20: CLI-061 | N20: 0 | O20: =IF(J20="","",J20-N20) -> 2 | Q20: =IFERROR(MasterData!$B20,"") -> DU Hospitality | R20: =IFERROR(MasterData!$C20,"") -> CRM | S20: =IFERROR(MasterData!$D20,"") | T20: =IFERROR(MasterData!$E20,"") | U20: =IFERROR(MasterData!$F20,"") | V20: =IFERROR(MasterData!$I20,"") | W20: =IFERROR(MasterData!$H20,"")
A21: CLI-061-POS-002 | B21: Speciality | C21: ARM | D21: F&B - Service | E21: Delhi | F21: Mid | I21: Hardik | J21: 2 | K21: Open | M21: CLI-061 | N21: 0 | O21: =IF(J21="","",J21-N21) -> 2 | Q21: =IFERROR(MasterData!$B21,"") -> Diva | R21: =IFERROR(MasterData!$C21,"") -> Cafe Manager | S21: =IFERROR(MasterData!$D21,"") | T21: =IFERROR(MasterData!$E21,"") | U21: =IFERROR(MasterData!$F21,"") | V21: =IFERROR(MasterData!$I21,"") | W21: =IFERROR(MasterData!$H21,"")
A22: CLI-061-POS-003 | B22: Speciality | C22: ARM | D22: F&B - Service | E22: Pune | F22: Mid | I22: Hardik | J22: 2 | K22: Open | M22: CLI-061 | N22: 0 | O22: =IF(J22="","",J22-N22) -> 2 | Q22: =IFERROR(MasterData!$B22,"") -> Donmai | R22: =IFERROR(MasterData!$C22,"") -> Cafe Supervisor | S22: =IFERROR(MasterData!$D22,"") | T22: =IFERROR(MasterData!$E22,"") | U22: =IFERROR(MasterData!$F22,"") | V22: =IFERROR(MasterData!$I22,"") | W22: =IFERROR(MasterData!$H22,"")
A23: CLI-061-POS-004 | B23: Speciality | C23: Executive Chef | D23: F&B - Kitchen | E23: Delhi | F23: Leadership | G23: 46085 | H23: 46104 | I23: Hardik | J23: 2 | K23: Closed | L23: Selected and Joining from 1st of May | M23: CLI-061 | N23: 1 | O23: =IF(J23="","",J23-N23) -> 1 | Q23: =IFERROR(MasterData!$B23,"") -> Doppler | R23: =IFERROR(MasterData!$C23,"") -> Captain | S23: =IFERROR(MasterData!$D23,"") | T23: =IFERROR(MasterData!$E23,"") | U23: =IFERROR(MasterData!$F23,"") | V23: =IFERROR(MasterData!$I23,"") | W23: =IFERROR(MasterData!$H23,"")
A24: CLI-061-POS-005 | B24: Speciality | C24: Executive Chef | D24: F&B - Kitchen | E24: Pune | F24: Leadership | I24: Hardik | J24: 1 | K24: Open | M24: CLI-061 | N24: 0 | O24: =IF(J24="","",J24-N24) -> 1 | Q24: =IFERROR(MasterData!$B24,"") -> Dough and Joe | R24: =IFERROR(MasterData!$C24,"") -> Cashier | S24: =IFERROR(MasterData!$D24,"") | T24: =IFERROR(MasterData!$E24,"") | U24: =IFERROR(MasterData!$F24,"") | V24: =IFERROR(MasterData!$I24,"") | W24: =IFERROR(MasterData!$H24,"")
A25: CLI-061-POS-006 | B25: Speciality | C25: Marketing Head | D25: Marketing & PR | E25: Delhi | F25: Leadership | G25: 46086 | H25: 46089 | I25: Hardik | J25: 1 | K25: Closed | M25: CLI-061 | N25: 1 | O25: =IF(J25="","",J25-N25) -> 0 | Q25: =IFERROR(MasterData!$B25,"") -> EDD | R25: =IFERROR(MasterData!$C25,"") -> Chef | S25: =IFERROR(MasterData!$D25,"") | T25: =IFERROR(MasterData!$E25,"") | U25: =IFERROR(MasterData!$F25,"") | V25: =IFERROR(MasterData!$I25,"") | W25: =IFERROR(MasterData!$H25,"")
A26: CLI-045-POS-001 | B26: Neighbourhood | C26: Community Manager | D26: Marketing & PR | E26: Bangalore | F26: Mid | I26: Hardik | J26: 1 | K26: Open | M26: CLI-045 | N26: 0 | O26: =IF(J26="","",J26-N26) -> 1 | Q26: =IFERROR(MasterData!$B26,"") -> FHPL | R26: =IFERROR(MasterData!$C26,"") -> Commi | S26: =IFERROR(MasterData!$D26,"") | T26: =IFERROR(MasterData!$E26,"") | U26: =IFERROR(MasterData!$F26,"") | V26: =IFERROR(MasterData!$I26,"") | W26: =IFERROR(MasterData!$H26,"")
A27: CLI-045-POS-002 | B27: Neighbourhood | C27: Community Manager | D27: Marketing & PR | E27: Mumbai | F27: Mid | I27: Hardik | J27: 1 | K27: Open | M27: CLI-045 | N27: 0 | O27: =IF(J27="","",J27-N27) -> 1 | Q27: =IFERROR(MasterData!$B27,"") -> Flavour Pots | R27: =IFERROR(MasterData!$C27,"") -> Commi 1 | S27: =IFERROR(MasterData!$D27,"") | T27: =IFERROR(MasterData!$E27,"") | U27: =IFERROR(MasterData!$F27,"") | V27: =IFERROR(MasterData!$I27,"") | W27: =IFERROR(MasterData!$H27,"")
A28: CLI-022-POS-001 | B28: EDD | C28: HR Head | D28: HR & Training | E28: Mumbai | F28: Senior | I28: Aakash | J28: 1 | K28: Open | M28: CLI-022 | N28: 0 | O28: =IF(J28="","",J28-N28) -> 1 | Q28: =IFERROR(MasterData!$B28,"") -> Food Square | R28: =IFERROR(MasterData!$C28,"") -> Commi 2 | S28: =IFERROR(MasterData!$D28,"") | T28: =IFERROR(MasterData!$E28,"") | U28: =IFERROR(MasterData!$F28,"") | V28: =IFERROR(MasterData!$I28,"") | W28: =IFERROR(MasterData!$H28,"")
A29: CLI-022-POS-002 | B29: EDD | C29: Sous Chef | D29: F&B - Kitchen | E29: Mumbai | F29: Senior | I29: Aakash | J29: 1 | K29: Open | M29: CLI-022 | N29: 0 | O29: =IF(J29="","",J29-N29) -> 1 | Q29: =IFERROR(MasterData!$B29,"") -> Foodmatters | R29: =IFERROR(MasterData!$C29,"") -> Commi 3 | S29: =IFERROR(MasterData!$D29,"") | T29: =IFERROR(MasterData!$E29,"") | U29: =IFERROR(MasterData!$F29,"") | V29: =IFERROR(MasterData!$I29,"") | W29: =IFERROR(MasterData!$H29,"")
A30: CLI-022-POS-003 | B30: EDD | C30: CDP | D30: F&B - Kitchen | E30: Mumbai | F30: Mid | I30: Aakash | J30: 1 | K30: Open | M30: CLI-022 | N30: 0 | O30: =IF(J30="","",J30-N30) -> 1 | Q30: =IFERROR(MasterData!$B30,"") -> Ghostkitchens | R30: =IFERROR(MasterData!$C30,"") -> Community Manager | S30: =IFERROR(MasterData!$D30,"") | T30: =IFERROR(MasterData!$E30,"") | U30: =IFERROR(MasterData!$F30,"") | V30: =IFERROR(MasterData!$I30,"") | W30: =IFERROR(MasterData!$H30,"")
A31: CLI-022-POS-004 | B31: EDD | C31: Commi | D31: F&B - Kitchen | E31: Mumbai | F31: Junior | I31: Aakash | J31: 5 | K31: Open | M31: CLI-022 | N31: 0 | O31: =IF(J31="","",J31-N31) -> 5 | Q31: =IFERROR(MasterData!$B31,"") -> Gupta Brands | R31: =IFERROR(MasterData!$C31,"") -> Content Strategist | S31: =IFERROR(MasterData!$D31,"") | T31: =IFERROR(MasterData!$E31,"") | U31: =IFERROR(MasterData!$F31,"") | V31: =IFERROR(MasterData!$I31,"") | W31: =IFERROR(MasterData!$H31,"")
A32: CLI-022-POS-005 | B32: EDD | C32: Captain | D32: F&B - Service | E32: Mumbai | F32: Junior | I32: Aakash | J32: 5 | K32: Open | M32: CLI-022 | N32: 0 | O32: =IF(J32="","",J32-N32) -> 5 | Q32: =IFERROR(MasterData!$B32,"") -> Huddle and Score | R32: =IFERROR(MasterData!$C32,"") -> Counter Sales | S32: =IFERROR(MasterData!$D32,"") | T32: =IFERROR(MasterData!$E32,"") | U32: =IFERROR(MasterData!$F32,"") | V32: =IFERROR(MasterData!$I32,"") | W32: =IFERROR(MasterData!$H32,"")
A33: CLI-038-POS-001 | B33: La Loca Maria | C33: Chef | D33: F&B - Kitchen | E33: Mumbai | F33: Leadership | I33: Edwin | J33: 0 | K33: Open | L33: Chef De Cuisine | M33: CLI-038 | N33: 0 | O33: =IF(J33="","",J33-N33) -> 0 | Q33: =IFERROR(MasterData!$B33,"") -> Hummingtree | R33: =IFERROR(MasterData!$C33,"") -> DCDP | S33: =IFERROR(MasterData!$D33,"") | T33: =IFERROR(MasterData!$E33,"") | U33: =IFERROR(MasterData!$F33,"") | V33: =IFERROR(MasterData!$I33,"") | W33: =IFERROR(MasterData!$H33,"")
A34: CLI-038-POS-002 | B34: La Loca Maria | C34: Sous Chef | D34: F&B - Kitchen | E34: Mumbai | F34: Senior | I34: Edwin | J34: 1 | K34: Open | M34: CLI-038 | N34: 0 | O34: =IF(J34="","",J34-N34) -> 1 | Q34: =IFERROR(MasterData!$B34,"") -> Hunger Inc | R34: =IFERROR(MasterData!$C34,"") -> Data Analyst | S34: =IFERROR(MasterData!$D34,"") | T34: =IFERROR(MasterData!$E34,"") | U34: =IFERROR(MasterData!$F34,"") | V34: =IFERROR(MasterData!$I34,"") | W34: =IFERROR(MasterData!$H34,"")
A35: CLI-038-POS-003 | B35: La Loca Maria | C35: Mixologist | D35: Bar & Beverages | E35: Mumbai | F35: Senior | I35: Edwin | J35: 1 | K35: Open | M35: CLI-038 | N35: 0 | O35: =IF(J35="","",J35-N35) -> 1 | Q35: =IFERROR(MasterData!$B35,"") -> Idoru | R35: =IFERROR(MasterData!$C35,"") -> Director of Operations | S35: =IFERROR(MasterData!$D35,"") | T35: =IFERROR(MasterData!$E35,"") | U35: =IFERROR(MasterData!$F35,"") | V35: =IFERROR(MasterData!$I35,"") | W35: =IFERROR(MasterData!$H35,"")
A36: CLI-038-POS-004 | B36: La Loca Maria | C36: Captain | D36: F&B - Service | E36: Mumbai | F36: Junior | I36: Edwin | J36: 10 | K36: Open | M36: CLI-038 | N36: 0 | O36: =IF(J36="","",J36-N36) -> 10 | Q36: =IFERROR(MasterData!$B36,"") -> Ikai | R36: =IFERROR(MasterData!$C36,"") -> Duty Manager | S36: =IFERROR(MasterData!$D36,"") | T36: =IFERROR(MasterData!$E36,"") | U36: =IFERROR(MasterData!$F36,"") | V36: =IFERROR(MasterData!$I36,"") | W36: =IFERROR(MasterData!$H36,"")
A37: CLI-038-POS-005 | B37: La Loca Maria | C37: Bartender | D37: Bar & Beverages | E37: Mumbai | F37: Junior | I37: Edwin | J37: 5 | K37: Open | M37: CLI-038 | N37: 0 | O37: =IF(J37="","",J37-N37) -> 5 | Q37: =IFERROR(MasterData!$B37,"") -> Izumi | R37: =IFERROR(MasterData!$C37,"") -> EA | S37: =IFERROR(MasterData!$D37,"") | T37: =IFERROR(MasterData!$E37,"") | U37: =IFERROR(MasterData!$F37,"") | V37: =IFERROR(MasterData!$I37,"") | W37: =IFERROR(MasterData!$H37,"")
A38: CLI-038-POS-006 | B38: La Loca Maria | C38: Commi | D38: F&B - Kitchen | E38: Mumbai | F38: Junior | I38: Edwin | J38: 10 | K38: Open | M38: CLI-038 | N38: 0 | O38: =IF(J38="","",J38-N38) -> 10 | Q38: =IFERROR(MasterData!$B38,"") -> Izumi - GOA | R38: =IFERROR(MasterData!$C38,"") -> Executive Chef | S38: =IFERROR(MasterData!$D38,"") | T38: =IFERROR(MasterData!$E38,"") | U38: =IFERROR(MasterData!$F38,"") | V38: =IFERROR(MasterData!$I38,"") | W38: =IFERROR(MasterData!$H38,"")
A39: CLI-015-POS-001 | B39: Circa 11 | C39: CDP | D39: F&B - Kitchen | E39: Bangalore | F39: Mid | I39: Edwin | J39: 1 | K39: Open | M39: CLI-015 | N39: 0 | O39: =IF(J39="","",J39-N39) -> 1 | Q39: =IFERROR(MasterData!$B39,"") -> Kaia | R39: =IFERROR(MasterData!$C39,"") -> F&B Associate | S39: =IFERROR(MasterData!$D39,"") | T39: =IFERROR(MasterData!$E39,"") | U39: =IFERROR(MasterData!$F39,"") | V39: =IFERROR(MasterData!$I39,"") | W39: =IFERROR(MasterData!$H39,"")
A40: CLI-015-POS-002 | B40: Circa 11 | C40: Bartender | D40: Bar & Beverages | E40: Bangalore | F40: Junior | I40: Edwin | J40: 1 | K40: Open | M40: CLI-015 | N40: 0 | O40: =IF(J40="","",J40-N40) -> 1 | Q40: =IFERROR(MasterData!$B40,"") -> Kohinoor Group | R40: =IFERROR(MasterData!$C40,"") -> F&B Controller | S40: =IFERROR(MasterData!$D40,"") | T40: =IFERROR(MasterData!$E40,"") | U40: =IFERROR(MasterData!$F40,"") | V40: =IFERROR(MasterData!$I40,"") | W40: =IFERROR(MasterData!$H40,"")
...

Sheet Candidate Pipeline
A1: 👤 CANDIDATE PIPELINE
A2: 💡 DB Cand ID links back to the Candidate Database. Select Client Name → Client ID auto-fills. Pipeline Cand ID auto-generates.
A3: Pipeline ID | B3: DB Cand ID | C3: Candidate Name | D3: Client Name | E3: Client ID | F3: Role Applied For | G3: Current Company | H3: City | I3: Stage | J3: Sourced By | K3: Date Added | L3: Last Updated | M3: Next Follow-up | N3: Client Feedback | O3: Remarks
A4: PIP-001 | B4: CAN-007 | C4: Lakshita Shaw | D4: Hunger Inc | E4: CLI-031 | F4: Steward | G4: Love & Latte Juhu | H4: Mumbai | I4: Candidate Dropped | J4: Edwin | K4: 46104 | P4: =IFERROR(MasterData!$B4,"") -> ABNAH | Q4: =IFERROR(MasterData!$C4,"") -> ARM | R4: =IFERROR(MasterData!$E4,"") -> Mumbai | S4: =IFERROR(MasterData!$G4,"") -> Sent to Client | T4: =IFERROR(MasterData!$I4,"") -> Edwin
A5: PIP-002 | C5: Keval Javadia | D5: Hunger Inc | E5: CLI-031 | F5: F&B Executive | G5: Baang | H5: Mumbai | I5: Rejected | J5: Mohit | K5: 46104 | P5: =IFERROR(MasterData!$B5,"") -> Abhinav Immigration | Q5: =IFERROR(MasterData!$C5,"") -> Assistant Bartender | R5: =IFERROR(MasterData!$E5,"") -> Delhi | S5: =IFERROR(MasterData!$G5,"") -> Interview Scheduled | T5: =IFERROR(MasterData!$I5,"") -> Manokamna
A6: PIP-003 | C6: Vedant Nimbre | D6: Hunger Inc | E6: CLI-031 | F6: Steward | G6: Rahega | H6: Mumbai | I6: Joined | J6: Mohit | K6: 46104 | P6: =IFERROR(MasterData!$B6,"") -> Adarsh Sweets | Q6: =IFERROR(MasterData!$C6,"") -> Assistant Front Office Manager | R6: =IFERROR(MasterData!$E6,"") -> Bangalore | S6: =IFERROR(MasterData!$G6,"") -> Result Awaited | T6: =IFERROR(MasterData!$I6,"") -> Hardik
A7: PIP-004 | C7: Priya Jerome Gonsalves | D7: Blondie | E7: CLI-014 | F7: FOE | G7: Fresher | H7: Mumbai | I7: Candidate Dropped | J7: Mohit | K7: 46104 | L7: 46104 | P7: =IFERROR(MasterData!$B7,"") -> Agarwal Biryani | Q7: =IFERROR(MasterData!$C7,"") -> Assistant Manager | R7: =IFERROR(MasterData!$E7,"") -> Hyderabad | S7: =IFERROR(MasterData!$G7,"") -> Selected | T7: =IFERROR(MasterData!$I7,"") -> Mohit
A8: PIP-005 | C8: Aarti Rokade | D8: Le 15 | E8: CLI-031 | F8: Barista | G8: Not working | H8: Mumbai | I8: Rejected | J8: Mohit | K8: 46104 | P8: =IFERROR(MasterData!$B8,"") -> All in | Q8: =IFERROR(MasterData!$C8,"") -> Assistant Outlet Manager | R8: =IFERROR(MasterData!$E8,"") -> Pune | S8: =IFERROR(MasterData!$G8,"") -> Rejected | T8: =IFERROR(MasterData!$I8,"") -> Aakash
A9: PIP-006 | C9: Sanskrita Ekawade | D9: Doppler | E9: CLI-020 | F9: Senior Barista | G9: Starbucks | H9: Mumbai | I9: Rejected | J9: Mohit | K9: 46104 | P9: =IFERROR(MasterData!$B9,"") -> Aria Communication | Q9: =IFERROR(MasterData!$C9,"") -> Assistant Stores Manager | R9: =IFERROR(MasterData!$E9,"") -> Goa | S9: =IFERROR(MasterData!$G9,"") -> Hold | T9: =IFERROR(MasterData!$I9,"")
A10: PIP-007 | C10: Chetan Medhekar | D10: Doppler | E10: CLI-020 | F10: Senior Barista | G10: Bouee Coffee Roasters | H10: Gujarat | I10: Rejected | J10: Mohit | K10: 46104 | P10: =IFERROR(MasterData!$B10,"") -> Atmosphere | Q10: =IFERROR(MasterData!$C10,"") -> Asst Cafe Manager | R10: =IFERROR(MasterData!$E10,"") -> Chennai | S10: =IFERROR(MasterData!$G10,"") -> Offer Sent | T10: =IFERROR(MasterData!$I10,"")
A11: PIP-008 | C11: Sangram Patil | D11: Neighbourhood | E11: CLI-045 | F11: Sous Chef | G11: None | H11: Mumbai | I11: Candidate Dropped | J11: Mohit | K11: 46104 | P11: =IFERROR(MasterData!$B11,"") -> August Café | Q11: =IFERROR(MasterData!$C11,"") -> Bar Lead | R11: =IFERROR(MasterData!$E11,"") -> Kolkata | S11: =IFERROR(MasterData!$G11,"") -> Offer Accepted | T11: =IFERROR(MasterData!$I11,"")
A12: PIP-009 | C12: Prajwal Sawant | D12: Blondie | E12: CLI-014 | F12: Commi 2 | G12: None | H12: Mumbai | I12: Candidate Dropped | J12: Mohit | K12: 46104 | P12: =IFERROR(MasterData!$B12,"") -> Aures hospitality | Q12: =IFERROR(MasterData!$C12,"") -> Bar Manager | R12: =IFERROR(MasterData!$E12,"") -> Ahmedabad | S12: =IFERROR(MasterData!$G12,"") -> Joined | T12: =IFERROR(MasterData!$I12,"")
A13: PIP-010 | C13: Ainul Khan | D13: Blondie | E13: CLI-014 | F13: Sous Chef | G13: The Oberoi,Mumbai | H13: Mumbai | I13: Offer Accepted | J13: Mohit | K13: 46104 | P13: =IFERROR(MasterData!$B13,"") -> BB | Q13: =IFERROR(MasterData!$C13,"") -> Bar Supervisor | R13: =IFERROR(MasterData!$E13,"") -> Jaipur | S13: =IFERROR(MasterData!$G13,"") -> Candidate Dropped | T13: =IFERROR(MasterData!$I13,"")
A14: PIP-011 | C14: Mihir Bagwe | D14: Blondie | E14: CLI-014 | F14: Commi 2 | G14: None | H14: Mumbai | I14: Candidate Dropped | J14: Mohit | K14: 46104 | P14: =IFERROR(MasterData!$B14,"") -> BTC | Q14: =IFERROR(MasterData!$C14,"") -> Barback | R14: =IFERROR(MasterData!$E14,"") -> Other | S14: =IFERROR(MasterData!$G14,"") | T14: =IFERROR(MasterData!$I14,"")
A15: PIP-012 | C15: Khuhbu Magar | D15: Bastian | E15: CLI-075 | F15: HR | G15: Milagro | H15: Mumbai | I15: Rejected | J15: Mohit | K15: 46104 | P15: =IFERROR(MasterData!$B15,"") -> Baesic Fit | Q15: =IFERROR(MasterData!$C15,"") -> Barista | R15: =IFERROR(MasterData!$E15,"") | S15: =IFERROR(MasterData!$G15,"") | T15: =IFERROR(MasterData!$I15,"")
A16: PIP-013 | C16: Pushkaraj Gurav | D16: Hunger Inc | E16: CLI-031 | F16: Captain | G16: Trident,Nariman Point | H16: Mumbai | I16: Rejected | J16: Mohit | K16: 46104 | P16: =IFERROR(MasterData!$B16,"") -> Bare | Q16: =IFERROR(MasterData!$C16,"") -> Barista Head | R16: =IFERROR(MasterData!$E16,"") | S16: =IFERROR(MasterData!$G16,"") | T16: =IFERROR(MasterData!$I16,"")
A17: PIP-014 | C17: Nishant Kadam | D17: ABNAH | E17: CLI-001 | F17: Bartender | G17: None | H17: Mumbai | I17: Rejected | J17: Mohit | K17: 46105 | P17: =IFERROR(MasterData!$B17,"") -> Blondie | Q17: =IFERROR(MasterData!$C17,"") -> Barista Trainer | R17: =IFERROR(MasterData!$E17,"") | S17: =IFERROR(MasterData!$G17,"") | T17: =IFERROR(MasterData!$I17,"")
D18: Speciality | E18: CLI-061 | F18: General Manager | G18: Fratterniti/EHV | H18: Delhi | I18: Interview Scheduled | J18: Hardik | K18: 46104 | L18: 46107 | M18: 46107 | P18: =IFERROR(MasterData!$B18,"") -> Circa 11 | Q18: =IFERROR(MasterData!$C18,"") -> Bartender | R18: =IFERROR(MasterData!$E18,"") | S18: =IFERROR(MasterData!$G18,"") | T18: =IFERROR(MasterData!$I18,"")
A19: PIP-016 | C19: Prakash Pradhan | D19: Speciality | E19: CLI-061 | F19: Head Chef | G19: Massive | H19: Delhi | I19: Selected | J19: Hardik | K19: 46104 | L19: 46104 | M19: 46109 | P19: =IFERROR(MasterData!$B19,"") -> CocoCart | Q19: =IFERROR(MasterData!$C19,"") -> CDP | R19: =IFERROR(MasterData!$E19,"") | S19: =IFERROR(MasterData!$G19,"") | T19: =IFERROR(MasterData!$I19,"")
A20: PIP-017 | B20: CAN-008 | C20: Akhil Chavan | D20: Izumi | E20: CLI-034 | F20: Bartender | G20: Impressario | H20: Hyderabad | I20: Offer Accepted | J20: Edwin | K20: 46105 | L20: 46105 | P20: =IFERROR(MasterData!$B20,"") -> DU Hospitality | Q20: =IFERROR(MasterData!$C20,"") -> CRM | R20: =IFERROR(MasterData!$E20,"") | S20: =IFERROR(MasterData!$G20,"") | T20: =IFERROR(MasterData!$I20,"")
A21: PIP-018 | B21: CAN-009 | C21: Saurabh Vengurlekar | D21: Hunger Inc | E21: CLI-031 | F21: Head Chef | G21: Cantina | H21: Mumbai | I21: Sent to Client | J21: Edwin | K21: 46105 | P21: =IFERROR(MasterData!$B21,"") -> Diva | Q21: =IFERROR(MasterData!$C21,"") -> Cafe Manager | R21: =IFERROR(MasterData!$E21,"") | S21: =IFERROR(MasterData!$G21,"") | T21: =IFERROR(MasterData!$I21,"")
A22: PIP-019 | C22: Prasad Parab | D22: ABNAH | E22: CLI-001 | F22: Bartender | G22: Foo | H22: Mumbai | I22: Rejected | J22: Mohit | K22: 46106 | P22: =IFERROR(MasterData!$B22,"") -> Donmai | Q22: =IFERROR(MasterData!$C22,"") -> Cafe Supervisor | R22: =IFERROR(MasterData!$E22,"") | S22: =IFERROR(MasterData!$G22,"") | T22: =IFERROR(MasterData!$I22,"")
A23: PIP-020 | C23: Moin Pawar | D23: ABNAH | E23: CLI-039 | F23: Barista | G23: Mc Donalds | H23: Mumbai | I23: Joined | J23: Mohit | K23: 46105 | L23: 46106 | M23: 46112 | P23: =IFERROR(MasterData!$B23,"") -> Doppler | Q23: =IFERROR(MasterData!$C23,"") -> Captain | R23: =IFERROR(MasterData!$E23,"") | S23: =IFERROR(MasterData!$G23,"") | T23: =IFERROR(MasterData!$I23,"")
A24: PIP-021 | C24: Dinesh Nishad | D24: Courtside | E24: CLI-014 | F24: Commi 1 | G24: None | H24: Mumbai | I24: Candidate Dropped | J24: Aakash | K24: 46140 | L24: 46140 | M24: 46140 | P24: =IFERROR(MasterData!$B24,"") -> Dough and Joe | Q24: =IFERROR(MasterData!$C24,"") -> Cashier | R24: =IFERROR(MasterData!$E24,"") | S24: =IFERROR(MasterData!$G24,"") | T24: =IFERROR(MasterData!$I24,"")
A25: PIP-022 | C25: Rashmi Walavalkar | D25: Courtside | E25: CLI-014 | F25: Commi 2 | G25: None | H25: Mumbai | I25: Candidate Dropped | J25: Aakash | K25: 46140 | L25: 46140 | M25: 46140 | P25: =IFERROR(MasterData!$B25,"") -> EDD | Q25: =IFERROR(MasterData!$C25,"") -> Chef | R25: =IFERROR(MasterData!$E25,"") | S25: =IFERROR(MasterData!$G25,"") | T25: =IFERROR(MasterData!$I25,"")
A26: PIP-023 | B26: CAN-033 | C26: Aarti Jaiswar | D26: Izumi | E26: CLI-034 | F26: Senior GRE | G26: ODE | H26: Mumbai | I26: Offer Accepted | J26: Edwin | K26: 46106 | L26: 46106 | P26: =IFERROR(MasterData!$B26,"") -> FHPL | Q26: =IFERROR(MasterData!$C26,"") -> Commi | R26: =IFERROR(MasterData!$E26,"") | S26: =IFERROR(MasterData!$G26,"") | T26: =IFERROR(MasterData!$I26,"")
A27: PIP-024 | C27: Pritam Bhindani | D27: Blondie | E27: CLI-014 | F27: Commi 2 | G27: Leela | H27: Mumbai | I27: Candidate Dropped | J27: Aakash | K27: 46106 | O27: DNR | P27: =IFERROR(MasterData!$B27,"") -> Flavour Pots | Q27: =IFERROR(MasterData!$C27,"") -> Commi 1 | R27: =IFERROR(MasterData!$E27,"") | S27: =IFERROR(MasterData!$G27,"") | T27: =IFERROR(MasterData!$I27,"")
A28: PIP-025 | C28: Purvi Mhambrey | D28: Bastian | E28: CLI-075 | F28: Social Media Manager | G28: TVA | H28: Mumbai | I28: Joined | J28: Aakash | K28: 46106 | M28: 46108 | P28: =IFERROR(MasterData!$B28,"") -> Food Square | Q28: =IFERROR(MasterData!$C28,"") -> Commi 2 | R28: =IFERROR(MasterData!$E28,"") | S28: =IFERROR(MasterData!$G28,"") | T28: =IFERROR(MasterData!$I28,"")
A29: PIP-026 | C29: Firoj Khan | D29: Doppler | E29: CLI-020 | F29: Captain | G29: Ananta Spa | H29: Jaipur | I29: Sent to Client | J29: Manokamna | K29: 46106 | P29: =IFERROR(MasterData!$B29,"") -> Foodmatters | Q29: =IFERROR(MasterData!$C29,"") -> Commi 3 | R29: =IFERROR(MasterData!$E29,"") | S29: =IFERROR(MasterData!$G29,"") | T29: =IFERROR(MasterData!$I29,"")
A30: PIP-027 | C30: Ami Desai | D30: Blondie | E30: CLI-014 | F30: Social Media Manager | G30: Bizspark ventures | H30: Mumbai | I30: Hold | J30: Aakash | K30: 46106 | M30: 46110 | P30: =IFERROR(MasterData!$B30,"") -> Ghostkitchens | Q30: =IFERROR(MasterData!$C30,"") -> Community Manager | R30: =IFERROR(MasterData!$E30,"") | S30: =IFERROR(MasterData!$G30,"") | T30: =IFERROR(MasterData!$I30,"")
A31: PIP-028 | C31: Trisha Karambar | D31: Blondie | E31: CLI-014 | F31: Social Media Manager | G31: Back Benchers Digital | H31: Mumbai | I31: Hold | J31: Aakash | K31: 46106 | M31: 46110 | P31: =IFERROR(MasterData!$B31,"") -> Gupta Brands | Q31: =IFERROR(MasterData!$C31,"") -> Content Strategist | R31: =IFERROR(MasterData!$E31,"") | S31: =IFERROR(MasterData!$G31,"") | T31: =IFERROR(MasterData!$I31,"")
A32: PIP-029 | C32: Omkar Shinde | D32: Milagro (SLH) | E32: CLI-014 | F32: Senior Barista | G32: Thee Wild Berry | H32: Mumbai | I32: Rejected | J32: Aakash | K32: 46106 | L32: 46133 | M32: 46133 | P32: =IFERROR(MasterData!$B32,"") -> Huddle and Score | Q32: =IFERROR(MasterData!$C32,"") -> Counter Sales | R32: =IFERROR(MasterData!$E32,"") | S32: =IFERROR(MasterData!$G32,"") | T32: =IFERROR(MasterData!$I32,"")
A33: PIP-030 | C33: Surendra Singh | D33: Doppler | E33: CLI-020 | F33: Captain | G33: St Regis | H33: Delhi | I33: Sent to Client | J33: Manokamna | K33: 46106 | P33: =IFERROR(MasterData!$B33,"") -> Hummingtree | Q33: =IFERROR(MasterData!$C33,"") -> DCDP | R33: =IFERROR(MasterData!$E33,"") | S33: =IFERROR(MasterData!$G33,"") | T33: =IFERROR(MasterData!$I33,"")
A34: PIP-031 | C34: Nengboi Haokip | D34: Blondie | E34: CLI-014 | F34: GRE | G34: Brunch and Cake | H34: Mumbai | I34: Candidate Dropped | J34: Aakash | K34: 46106 | O34: DNR | P34: =IFERROR(MasterData!$B34,"") -> Hunger Inc | Q34: =IFERROR(MasterData!$C34,"") -> Data Analyst | R34: =IFERROR(MasterData!$E34,"") | S34: =IFERROR(MasterData!$G34,"") | T34: =IFERROR(MasterData!$I34,"")
A35: PIP-032 | C35: Vinay Nair | D35: Donmai | E35: CLI-019 | F35: Commi 1 | G35: None | H35: Mumbai | I35: Candidate Dropped | J35: Aakash | K35: 46106 | L35: 46106 | M35: 46111 | O35: Persuing a different opportunity in Ahmedabad | P35: =IFERROR(MasterData!$B35,"") -> Idoru | Q35: =IFERROR(MasterData!$C35,"") -> Director of Operations | R35: =IFERROR(MasterData!$E35,"") | S35: =IFERROR(MasterData!$G35,"") | T35: =IFERROR(MasterData!$I35,"")
A36: PIP-033 | B36: CAN-037 | C36: Imli Longchari | D36: Izumi | E36: CLI-034 | F36: Senior Bartender | G36: Gunpowder | H36: Hyderabad | I36: Rejected | J36: Edwin | K36: 46106 | L36: 46106 | M36: 46107 | N36: Not upto the mark | O36: I have shared it with Circa 11 | P36: =IFERROR(MasterData!$B36,"") -> Ikai | Q36: =IFERROR(MasterData!$C36,"") -> Duty Manager | R36: =IFERROR(MasterData!$E36,"") | S36: =IFERROR(MasterData!$G36,"") | T36: =IFERROR(MasterData!$I36,"")
A37: PIP-034 | C37: Nadeem Merchant | D37: HNH Salad | E37: CLI-073 | F37: Purchase | H37: Mumbai | I37: Rejected | J37: Aakash | K37: 46106 | N37: Not upto the mark | P37: =IFERROR(MasterData!$B37,"") -> Izumi | Q37: =IFERROR(MasterData!$C37,"") -> EA | R37: =IFERROR(MasterData!$E37,"") | S37: =IFERROR(MasterData!$G37,"") | T37: =IFERROR(MasterData!$I37,"")
A38: PIP-035 | C38: Satish Jadhav | D38: HNH Salad | E38: CLI-073 | F38: Stores Manager | H38: Mumbai | I38: Rejected | J38: Aakash | K38: 46106 | P38: =IFERROR(MasterData!$B38,"") -> Izumi - GOA | Q38: =IFERROR(MasterData!$C38,"") -> Executive Chef | R38: =IFERROR(MasterData!$E38,"") | S38: =IFERROR(MasterData!$G38,"") | T38: =IFERROR(MasterData!$I38,"")
A39: PIP-036 | C39: Vikash Kumar | D39: Doppler | E39: CLI-020 | F39: Captain | G39: Hotel Cross Lane | H39: Other | I39: Candidate Dropped | J39: Aakash | K39: 46106 | P39: =IFERROR(MasterData!$B39,"") -> Kaia | Q39: =IFERROR(MasterData!$C39,"") -> F&B Associate | R39: =IFERROR(MasterData!$E39,"") | S39: =IFERROR(MasterData!$G39,"") | T39: =IFERROR(MasterData!$I39,"")
A40: PIP-037 | C40: Aquib Fayaz | D40: Doppler | E40: CLI-020 | F40: Senior Barista | G40: None | H40: Delhi | I40: Candidate Dropped | J40: Aakash | K40: 46106 | M40: 46108 | P40: =IFERROR(MasterData!$B40,"") -> Kohinoor Group | Q40: =IFERROR(MasterData!$C40,"") -> F&B Controller | R40: =IFERROR(MasterData!$E40,"") | S40: =IFERROR(MasterData!$G40,"") | T40: =IFERROR(MasterData!$I40,"")
...

Sheet Dashboard
A1: 📊 RECRUITMENT DASHBOARD — Auto-updates. No manual entry needed here.
A3: LIVE OVERVIEW
A4: Open Positions | B4: Total Seats Open | C4: Seats Filled | D4: Total In Pipeline | E4: Sent to Client | F4: Offers Accepted | G4: Candidate Dropped | H4: Joined
A5: =COUNTIF('Open Positions'!K:K,"Open") -> 101 | B5: =SUMIF('Open Positions'!K:K,"Open",'Open Positions'!J:J) -> 383 | C5: =SUMIF('Open Positions'!K:K,"Open",'Open Positions'!N:N) -> 5 | D5: =COUNTA('Candidate Pipeline'!C4:C998)-COUNTIF('Candidate Pipeline'!I4:I998,"Joined")-COUNTIF('Candidate Pipeline'!I4:I998,"Candidate Dropped") -> 202 | E5: =COUNTIF('Candidate Pipeline'!I:I,"Sent to Client") -> 34 | F5: =COUNTIF('Candidate Pipeline'!I:I,"Offer Accepted") -> 11 | G5: =COUNTIF('Candidate Pipeline'!I:I,"Candidate Dropped") -> 65 | H5: =COUNTIF('Candidate Pipeline'!I:I,"Joined") -> 13
A7: PIPELINE STAGE BREAKDOWN | E7: RECRUITER STATS
A8: Stage | B8: Count | C8: % of Pipeline | E8: Recruiter | F8: Open Seats | G8: In Pipeline | H8: Joined
A9: Sent to Client | B9: =COUNTIF('Candidate Pipeline'!I:I,"Sent to Client") -> 34 | C9: =IFERROR(COUNTIF('Candidate Pipeline'!I:I,"Sent to Client")/COUNTA('Candidate Pipeline'!C4:C998),0) -> 0.12142857 | E9: Edwin | F9: =SUMIFS('Open Positions'!J:J,'Open Positions'!I:I,"Edwin",'Open Positions'!K:K,"Open") -> 62 | G9: =COUNTIFS('Candidate Pipeline'!J:J,"Edwin",'Candidate Pipeline'!I:I,"<>Joined",'Candidate Pipeline'!I:I,"<>Candidate Dropped") -> 16 | H9: =COUNTIFS('Candidate Pipeline'!J:J,"Edwin",'Candidate Pipeline'!I:I,"Joined") -> 1
A10: Interview Scheduled | B10: =COUNTIF('Candidate Pipeline'!I:I,"Interview Scheduled") -> 88 | C10: =IFERROR(COUNTIF('Candidate Pipeline'!I:I,"Interview Scheduled")/COUNTA('Candidate Pipeline'!C4:C998),0) -> 0.31428571 | E10: Manokamna | F10: =SUMIFS('Open Positions'!J:J,'Open Positions'!I:I,"Manokamna",'Open Positions'!K:K,"Open") -> 54 | G10: =COUNTIFS('Candidate Pipeline'!J:J,"Manokamna",'Candidate Pipeline'!I:I,"<>Joined",'Candidate Pipeline'!I:I,"<>Candidate Dropped") -> 2 | H10: =COUNTIFS('Candidate Pipeline'!J:J,"Manokamna",'Candidate Pipeline'!I:I,"Joined") -> 0
A11: Result Awaited | B11: =COUNTIF('Candidate Pipeline'!I:I,"Result Awaited") -> 9 | C11: =IFERROR(COUNTIF('Candidate Pipeline'!I:I,"Result Awaited")/COUNTA('Candidate Pipeline'!C4:C998),0) -> 0.032142857 | E11: Hardik | F11: =SUMIFS('Open Positions'!J:J,'Open Positions'!I:I,"Hardik",'Open Positions'!K:K,"Open") -> 17 | G11: =COUNTIFS('Candidate Pipeline'!J:J,"Hardik",'Candidate Pipeline'!I:I,"<>Joined",'Candidate Pipeline'!I:I,"<>Candidate Dropped") -> 30 | H11: =COUNTIFS('Candidate Pipeline'!J:J,"Hardik",'Candidate Pipeline'!I:I,"Joined") -> 2
A12: Selected | B12: =COUNTIF('Candidate Pipeline'!I:I,"Selected") -> 20 | C12: =IFERROR(COUNTIF('Candidate Pipeline'!I:I,"Selected")/COUNTA('Candidate Pipeline'!C4:C998),0) -> 0.071428571 | E12: Mohit | F12: =SUMIFS('Open Positions'!J:J,'Open Positions'!I:I,"Mohit",'Open Positions'!K:K,"Open") -> 177 | G12: =COUNTIFS('Candidate Pipeline'!J:J,"Mohit",'Candidate Pipeline'!I:I,"<>Joined",'Candidate Pipeline'!I:I,"<>Candidate Dropped") -> 63 | H12: =COUNTIFS('Candidate Pipeline'!J:J,"Mohit",'Candidate Pipeline'!I:I,"Joined") -> 4
A13: Rejected | B13: =COUNTIF('Candidate Pipeline'!I:I,"Rejected") -> 34 | C13: =IFERROR(COUNTIF('Candidate Pipeline'!I:I,"Rejected")/COUNTA('Candidate Pipeline'!C4:C998),0) -> 0.12142857 | E13: Aakash | F13: =SUMIFS('Open Positions'!J:J,'Open Positions'!I:I,"Aakash",'Open Positions'!K:K,"Open") -> 73 | G13: =COUNTIFS('Candidate Pipeline'!J:J,"Aakash",'Candidate Pipeline'!I:I,"<>Joined",'Candidate Pipeline'!I:I,"<>Candidate Dropped") -> 91 | H13: =COUNTIFS('Candidate Pipeline'!J:J,"Aakash",'Candidate Pipeline'!I:I,"Joined") -> 6
A14: Hold | B14: =COUNTIF('Candidate Pipeline'!I:I,"Hold") -> 7 | C14: =IFERROR(COUNTIF('Candidate Pipeline'!I:I,"Hold")/COUNTA('Candidate Pipeline'!C4:C998),0) -> 0.025
A15: Offer Sent | B15: =COUNTIF('Candidate Pipeline'!I:I,"Offer Sent") -> 0 | C15: =IFERROR(COUNTIF('Candidate Pipeline'!I:I,"Offer Sent")/COUNTA('Candidate Pipeline'!C4:C998),0) -> 0
A16: Offer Accepted | B16: =COUNTIF('Candidate Pipeline'!I:I,"Offer Accepted") -> 11 | C16: =IFERROR(COUNTIF('Candidate Pipeline'!I:I,"Offer Accepted")/COUNTA('Candidate Pipeline'!C4:C998),0) -> 0.039285714
A17: Joined | B17: =COUNTIF('Candidate Pipeline'!I:I,"Joined") -> 13 | C17: =IFERROR(COUNTIF('Candidate Pipeline'!I:I,"Joined")/COUNTA('Candidate Pipeline'!C4:C998),0) -> 0.046428571
A18: Candidate Dropped | B18: =COUNTIF('Candidate Pipeline'!I:I,"Candidate Dropped") -> 65 | C18: =IFERROR(COUNTIF('Candidate Pipeline'!I:I,"Candidate Dropped")/COUNTA('Candidate Pipeline'!C4:C998),0) -> 0.23214286
A20: CLIENT ACTIVITY — updates automatically
A21: Every client added to Open Positions appears here automatically.
A22: Client Name | B22: Client ID | C22: Open Positions | D22: Total Seats | E22: Filled | F22: Remaining | G22: In Pipeline | H22: Joined
A23: ABNAH | B23: {=IF(A23="","",IFERROR(INDEX(MasterData!$A$4:$A$500,MATCH(A23,MasterData!$B$4:$B$500,0)),""))} -> CLI-001 | C23: =IF(A23="","",COUNTIFS('Open Positions'!B:B,A23,'Open Positions'!K:K,"Open")) -> 13 | D23: =IF(A23="","",SUMIFS('Open Positions'!J:J,'Open Positions'!B:B,A23,'Open Positions'!K:K,"Open")) -> 54 | E23: =IF(A23="","",SUMIFS('Open Positions'!N:N,'Open Positions'!B:B,A23,'Open Positions'!K:K,"Open")) -> 0 | F23: =IF(A23="","",SUMIFS('Open Positions'!O:O,'Open Positions'!B:B,A23,'Open Positions'!K:K,"Open")) -> 16 | G23: =IF(A23="","",COUNTIFS('Candidate Pipeline'!D:D,A23,'Candidate Pipeline'!I:I,"<>Joined",'Candidate Pipeline'!I:I,"<>Candidate Dropped")) -> 29 | H23: =IF(A23="","",COUNTIFS('Candidate Pipeline'!D:D,A23,'Candidate Pipeline'!I:I,"Joined")) -> 1
A24: Abhinav Immigration | B24: {=IF(A24="","",IFERROR(INDEX(MasterData!$A$4:$A$500,MATCH(A24,MasterData!$B$4:$B$500,0)),""))} -> CLI-002 | C24: =IF(A24="","",COUNTIFS('Open Positions'!B:B,A24,'Open Positions'!K:K,"Open")) -> 0 | D24: =IF(A24="","",SUMIFS('Open Positions'!J:J,'Open Positions'!B:B,A24,'Open Positions'!K:K,"Open")) -> 0 | E24: =IF(A24="","",SUMIFS('Open Positions'!N:N,'Open Positions'!B:B,A24,'Open Positions'!K:K,"Open")) -> 0 | F24: =IF(A24="","",SUMIFS('Open Positions'!O:O,'Open Positions'!B:B,A24,'Open Positions'!K:K,"Open")) -> 0 | G24: =IF(A24="","",COUNTIFS('Candidate Pipeline'!D:D,A24,'Candidate Pipeline'!I:I,"<>Joined",'Candidate Pipeline'!I:I,"<>Candidate Dropped")) -> 0 | H24: =IF(A24="","",COUNTIFS('Candidate Pipeline'!D:D,A24,'Candidate Pipeline'!I:I,"Joined")) -> 0
A25: Adarsh Sweets | B25: {=IF(A25="","",IFERROR(INDEX(MasterData!$A$4:$A$500,MATCH(A25,MasterData!$B$4:$B$500,0)),""))} -> CLI-003 | C25: =IF(A25="","",COUNTIFS('Open Positions'!B:B,A25,'Open Positions'!K:K,"Open")) -> 0 | D25: =IF(A25="","",SUMIFS('Open Positions'!J:J,'Open Positions'!B:B,A25,'Open Positions'!K:K,"Open")) -> 0 | E25: =IF(A25="","",SUMIFS('Open Positions'!N:N,'Open Positions'!B:B,A25,'Open Positions'!K:K,"Open")) -> 0 | F25: =IF(A25="","",SUMIFS('Open Positions'!O:O,'Open Positions'!B:B,A25,'Open Positions'!K:K,"Open")) -> 0 | G25: =IF(A25="","",COUNTIFS('Candidate Pipeline'!D:D,A25,'Candidate Pipeline'!I:I,"<>Joined",'Candidate Pipeline'!I:I,"<>Candidate Dropped")) -> 0 | H25: =IF(A25="","",COUNTIFS('Candidate Pipeline'!D:D,A25,'Candidate Pipeline'!I:I,"Joined")) -> 0
A26: Agarwal Biryani | B26: {=IF(A26="","",IFERROR(INDEX(MasterData!$A$4:$A$500,MATCH(A26,MasterData!$B$4:$B$500,0)),""))} -> CLI-004 | C26: =IF(A26="","",COUNTIFS('Open Positions'!B:B,A26,'Open Positions'!K:K,"Open")) -> 0 | D26: =IF(A26="","",SUMIFS('Open Positions'!J:J,'Open Positions'!B:B,A26,'Open Positions'!K:K,"Open")) -> 0 | E26: =IF(A26="","",SUMIFS('Open Positions'!N:N,'Open Positions'!B:B,A26,'Open Positions'!K:K,"Open")) -> 0 | F26: =IF(A26="","",SUMIFS('Open Positions'!O:O,'Open Positions'!B:B,A26,'Open Positions'!K:K,"Open")) -> 0 | G26: =IF(A26="","",COUNTIFS('Candidate Pipeline'!D:D,A26,'Candidate Pipeline'!I:I,"<>Joined",'Candidate Pipeline'!I:I,"<>Candidate Dropped")) -> 0 | H26: =IF(A26="","",COUNTIFS('Candidate Pipeline'!D:D,A26,'Candidate Pipeline'!I:I,"Joined")) -> 0
A27: All in | B27: {=IF(A27="","",IFERROR(INDEX(MasterData!$A$4:$A$500,MATCH(A27,MasterData!$B$4:$B$500,0)),""))} -> CLI-005 | C27: =IF(A27="","",COUNTIFS('Open Positions'!B:B,A27,'Open Positions'!K:K,"Open")) -> 7 | D27: =IF(A27="","",SUMIFS('Open Positions'!J:J,'Open Positions'!B:B,A27,'Open Positions'!K:K,"Open")) -> 19 | E27: =IF(A27="","",SUMIFS('Open Positions'!N:N,'Open Positions'!B:B,A27,'Open Positions'!K:K,"Open")) -> 0 | F27: =IF(A27="","",SUMIFS('Open Positions'!O:O,'Open Positions'!B:B,A27,'Open Positions'!K:K,"Open")) -> 18 | G27: =IF(A27="","",COUNTIFS('Candidate Pipeline'!D:D,A27,'Candidate Pipeline'!I:I,"<>Joined",'Candidate Pipeline'!I:I,"<>Candidate Dropped")) -> 14 | H27: =IF(A27="","",COUNTIFS('Candidate Pipeline'!D:D,A27,'Candidate Pipeline'!I:I,"Joined")) -> 1
A28: Aria Communication | B28: {=IF(A28="","",IFERROR(INDEX(MasterData!$A$4:$A$500,MATCH(A28,MasterData!$B$4:$B$500,0)),""))} -> CLI-006 | C28: =IF(A28="","",COUNTIFS('Open Positions'!B:B,A28,'Open Positions'!K:K,"Open")) -> 0 | D28: =IF(A28="","",SUMIFS('Open Positions'!J:J,'Open Positions'!B:B,A28,'Open Positions'!K:K,"Open")) -> 0 | E28: =IF(A28="","",SUMIFS('Open Positions'!N:N,'Open Positions'!B:B,A28,'Open Positions'!K:K,"Open")) -> 0 | F28: =IF(A28="","",SUMIFS('Open Positions'!O:O,'Open Positions'!B:B,A28,'Open Positions'!K:K,"Open")) -> 0 | G28: =IF(A28="","",COUNTIFS('Candidate Pipeline'!D:D,A28,'Candidate Pipeline'!I:I,"<>Joined",'Candidate Pipeline'!I:I,"<>Candidate Dropped")) -> 0 | H28: =IF(A28="","",COUNTIFS('Candidate Pipeline'!D:D,A28,'Candidate Pipeline'!I:I,"Joined")) -> 0
A29: Atmosphere | B29: {=IF(A29="","",IFERROR(INDEX(MasterData!$A$4:$A$500,MATCH(A29,MasterData!$B$4:$B$500,0)),""))} -> CLI-007 | C29: =IF(A29="","",COUNTIFS('Open Positions'!B:B,A29,'Open Positions'!K:K,"Open")) -> 0 | D29: =IF(A29="","",SUMIFS('Open Positions'!J:J,'Open Positions'!B:B,A29,'Open Positions'!K:K,"Open")) -> 0 | E29: =IF(A29="","",SUMIFS('Open Positions'!N:N,'Open Positions'!B:B,A29,'Open Positions'!K:K,"Open")) -> 0 | F29: =IF(A29="","",SUMIFS('Open Positions'!O:O,'Open Positions'!B:B,A29,'Open Positions'!K:K,"Open")) -> 0 | G29: =IF(A29="","",COUNTIFS('Candidate Pipeline'!D:D,A29,'Candidate Pipeline'!I:I,"<>Joined",'Candidate Pipeline'!I:I,"<>Candidate Dropped")) -> 0 | H29: =IF(A29="","",COUNTIFS('Candidate Pipeline'!D:D,A29,'Candidate Pipeline'!I:I,"Joined")) -> 0
A30: August Café | B30: {=IF(A30="","",IFERROR(INDEX(MasterData!$A$4:$A$500,MATCH(A30,MasterData!$B$4:$B$500,0)),""))} -> CLI-008 | C30: =IF(A30="","",COUNTIFS('Open Positions'!B:B,A30,'Open Positions'!K:K,"Open")) -> 0 | D30: =IF(A30="","",SUMIFS('Open Positions'!J:J,'Open Positions'!B:B,A30,'Open Positions'!K:K,"Open")) -> 0 | E30: =IF(A30="","",SUMIFS('Open Positions'!N:N,'Open Positions'!B:B,A30,'Open Positions'!K:K,"Open")) -> 0 | F30: =IF(A30="","",SUMIFS('Open Positions'!O:O,'Open Positions'!B:B,A30,'Open Positions'!K:K,"Open")) -> 0 | G30: =IF(A30="","",COUNTIFS('Candidate Pipeline'!D:D,A30,'Candidate Pipeline'!I:I,"<>Joined",'Candidate Pipeline'!I:I,"<>Candidate Dropped")) -> 0 | H30: =IF(A30="","",COUNTIFS('Candidate Pipeline'!D:D,A30,'Candidate Pipeline'!I:I,"Joined")) -> 0
A31: Aures hospitality | B31: {=IF(A31="","",IFERROR(INDEX(MasterData!$A$4:$A$500,MATCH(A31,MasterData!$B$4:$B$500,0)),""))} -> CLI-009 | C31: =IF(A31="","",COUNTIFS('Open Positions'!B:B,A31,'Open Positions'!K:K,"Open")) -> 0 | D31: =IF(A31="","",SUMIFS('Open Positions'!J:J,'Open Positions'!B:B,A31,'Open Positions'!K:K,"Open")) -> 0 | E31: =IF(A31="","",SUMIFS('Open Positions'!N:N,'Open Positions'!B:B,A31,'Open Positions'!K:K,"Open")) -> 0 | F31: =IF(A31="","",SUMIFS('Open Positions'!O:O,'Open Positions'!B:B,A31,'Open Positions'!K:K,"Open")) -> 0 | G31: =IF(A31="","",COUNTIFS('Candidate Pipeline'!D:D,A31,'Candidate Pipeline'!I:I,"<>Joined",'Candidate Pipeline'!I:I,"<>Candidate Dropped")) -> 0 | H31: =IF(A31="","",COUNTIFS('Candidate Pipeline'!D:D,A31,'Candidate Pipeline'!I:I,"Joined")) -> 0
A32: BB | B32: {=IF(A32="","",IFERROR(INDEX(MasterData!$A$4:$A$500,MATCH(A32,MasterData!$B$4:$B$500,0)),""))} -> CLI-010 | C32: =IF(A32="","",COUNTIFS('Open Positions'!B:B,A32,'Open Positions'!K:K,"Open")) -> 0 | D32: =IF(A32="","",SUMIFS('Open Positions'!J:J,'Open Positions'!B:B,A32,'Open Positions'!K:K,"Open")) -> 0 | E32: =IF(A32="","",SUMIFS('Open Positions'!N:N,'Open Positions'!B:B,A32,'Open Positions'!K:K,"Open")) -> 0 | F32: =IF(A32="","",SUMIFS('Open Positions'!O:O,'Open Positions'!B:B,A32,'Open Positions'!K:K,"Open")) -> 0 | G32: =IF(A32="","",COUNTIFS('Candidate Pipeline'!D:D,A32,'Candidate Pipeline'!I:I,"<>Joined",'Candidate Pipeline'!I:I,"<>Candidate Dropped")) -> 0 | H32: =IF(A32="","",COUNTIFS('Candidate Pipeline'!D:D,A32,'Candidate Pipeline'!I:I,"Joined")) -> 0
A33: BTC | B33: {=IF(A33="","",IFERROR(INDEX(MasterData!$A$4:$A$500,MATCH(A33,MasterData!$B$4:$B$500,0)),""))} -> CLI-011 | C33: =IF(A33="","",COUNTIFS('Open Positions'!B:B,A33,'Open Positions'!K:K,"Open")) -> 0 | D33: =IF(A33="","",SUMIFS('Open Positions'!J:J,'Open Positions'!B:B,A33,'Open Positions'!K:K,"Open")) -> 0 | E33: =IF(A33="","",SUMIFS('Open Positions'!N:N,'Open Positions'!B:B,A33,'Open Positions'!K:K,"Open")) -> 0 | F33: =IF(A33="","",SUMIFS('Open Positions'!O:O,'Open Positions'!B:B,A33,'Open Positions'!K:K,"Open")) -> 0 | G33: =IF(A33="","",COUNTIFS('Candidate Pipeline'!D:D,A33,'Candidate Pipeline'!I:I,"<>Joined",'Candidate Pipeline'!I:I,"<>Candidate Dropped")) -> 0 | H33: =IF(A33="","",COUNTIFS('Candidate Pipeline'!D:D,A33,'Candidate Pipeline'!I:I,"Joined")) -> 0
A34: Baesic Fit | B34: {=IF(A34="","",IFERROR(INDEX(MasterData!$A$4:$A$500,MATCH(A34,MasterData!$B$4:$B$500,0)),""))} -> CLI-012 | C34: =IF(A34="","",COUNTIFS('Open Positions'!B:B,A34,'Open Positions'!K:K,"Open")) -> 0 | D34: =IF(A34="","",SUMIFS('Open Positions'!J:J,'Open Positions'!B:B,A34,'Open Positions'!K:K,"Open")) -> 0 | E34: =IF(A34="","",SUMIFS('Open Positions'!N:N,'Open Positions'!B:B,A34,'Open Positions'!K:K,"Open")) -> 0 | F34: =IF(A34="","",SUMIFS('Open Positions'!O:O,'Open Positions'!B:B,A34,'Open Positions'!K:K,"Open")) -> 0 | G34: =IF(A34="","",COUNTIFS('Candidate Pipeline'!D:D,A34,'Candidate Pipeline'!I:I,"<>Joined",'Candidate Pipeline'!I:I,"<>Candidate Dropped")) -> 0 | H34: =IF(A34="","",COUNTIFS('Candidate Pipeline'!D:D,A34,'Candidate Pipeline'!I:I,"Joined")) -> 0
... A94: Zima | B94: {=IF(A94="","",IFERROR(INDEX(MasterData!$A$4:$A$500,MATCH(A94,MasterData!$B$4:$B$500,0)),""))} -> CLI-072 | C94: =IF(A94="","",COUNTIFS('Open Positions'!B:B,A94,'Open Positions'!K:K,"Open")) -> 0 | D94: =IF(A94="","",SUMIFS('Open Positions'!J:J,'Open Positions'!B:B,A94,'Open Positions'!K:K,"Open")) -> 0 | E94: =IF(A94="","",SUMIFS('Open Positions'!N:N,'Open Positions'!B:B,A94,'Open Positions'!K:K,"Open")) -> 0 | F94: =IF(A94="","",SUMIFS('Open Positions'!O:O,'Open Positions'!B:B,A94,'Open Positions'!K:K,"Open")) -> 0 | G94: =IF(A94="","",COUNTIFS('Candidate Pipeline'!D:D,A94,'Candidate Pipeline'!I:I,"<>Joined",'Candidate Pipeline'!I:I,"<>Candidate Dropped")) -> 0 | H94: =IF(A94="","",COUNTIFS('Candidate Pipeline'!D:D,A94,'Candidate Pipeline'!I:I,"Joined")) -> 0
