Workbook

Sheet Candidate Database
A1: A
A2: 💡 This is your universal talent record. Log every person you speak to. Tag to a client in col U to auto-populate the Client Tracker.
A3: Cand ID | B3: Name | C3: Entered By | D3: Phone Number | E3: Role | F3: Sub Role | G3: Current Salary | H3: Expected Salary | I3: City | J3: Area (Mumbai) | K3: Gender | L3: Education Level | M3: Work Experience | N3: Source | O3: Candidate Tags | P3: Binge Screening Remarks | Q3: Notes | R3: CV Link | S3: Date of Entry | T3: Interview Date | U3: Assigned To Client
A4: =IF(B4="","","CAN-"&TEXT(1,"000")) -> CAN-001 | B4: Ajay Dahiya | C4: Hardik | D4: 95557 21081 | E4: General Manager | F4: Cluster | G4: 95k | H4: 120k | I4: Delhi | J4: Other | K4: Male | L4: Hotel Management | M4: More than 2 years | N4: LinkedIn | R4: Resume Ajay Dahiya (1) (2).pdf | S4: 46104 | T4: 46104 | U4: Speciality | W4: ARM | X4: LinkedIn | Z4: Mumbai
A5: =IF(B5="","","CAN-"&TEXT(2,"000")) -> CAN-002 | B5: Pushkaraj Gurav | C5: Mohit | D5: 9921511411 | E5: Captain | G5: 20k | H5: 25k | I5: Mumbai | J5: Other | K5: Male | L5: Hotel Management | M5: More than 2 years | N5: Reference from Candidate | R5: Pushkaraj Gurav_Resume.pdf | S5: 46104 | W5: Assistant Bartender | X5: Indeed | Z5: Delhi
A6: =IF(B6="","","CAN-"&TEXT(3,"000")) -> CAN-003 | B6: Chandan Das | C6: Mohit | D6: 7076785991 | E6: Steward | G6: 15k | H6: 20k | I6: Mumbai | J6: Kurla | K6: Male | L6: SSC | M6: 1-2 years | N6: Reference from Candidate | R6: chandan das new cv (2).pdf | S6: 46104 | W6: Assistant Front Office Manager | X6: Naukri | Z6: Bangalore
A7: =IF(B7="","","CAN-"&TEXT(4,"000")) -> CAN-004 | B7: Nishant Kadam | C7: Mohit | D7: 9820505290 | E7: Assistant Bartender | G7: 15k | H7: 20k | I7: Mumbai | J7: Bandra | K7: Male | L7: Graduate | M7: 1-2 years | N7: Reference from Candidate | R7: 8AC102DE-4769-4A96-B1B5-479780006D2C.pdf | S7: 46104 | W7: Assistant Manager | X7: Reference from Candidate | Z7: Hyderabad
A8: =IF(B8="","","CAN-"&TEXT(5,"000")) -> CAN-005 | B8: Prakash Pradhan | C8: Hardik | D8: 93150 95662 | E8: Head Chef | F8: Chinese | G8: 85k | H8: 100k | I8: Delhi | J8: VK | K8: Male | L8: Hotel Management | M8: More than 2 Years | N8: LinkedIn | R8: Prakash Chef cv new.pdf | S8: 46104 | T8: 46099 | U8: Speciality | W8: Assistant Outlet Manager | X8: Inbound | Z8: Pune
A9: =IF(B9="","","CAN-"&TEXT(6,"000")) -> CAN-006 | B9: Veeraj Kamath | C9: Hardik | D9: 91364 04715 | E9: RM | F9: Ops | G9: 60k++ | H9: 75k++ | I9: Goa | K9: Male | L9: Hotel Management | M9: More than 2 Years | N9: LinkedIn | R9: Veeraaj Kamath_Resume.pdf | S9: 46104 | T9: 46105 | U9: Milagro (SLH) | W9: Assistant Stores Manager | X9: WhatsApp | Z9: Goa
A10: =IF(B10="","","CAN-"&TEXT(7,"000")) -> CAN-007 | B10: Lakshita Shaw | C10: Edwin | D10: 7045441922 | E10: Steward | F10: FOH | G10: 15k | H10: 20k | I10: Mumbai | J10: Juhu | K10: Female | L10: HSC | M10: 6 months-1 year | N10: Reference from Candidate | Q10: Kinshuks Sister | R10: Lakshita Shaw.pdf | S10: 46104 | T10: 46105 | U10: Hunger Inc | W10: Asst Cafe Manager | X10: Other | Z10: Chennai
A11: =IF(B11="","","CAN-"&TEXT(8,"000")) -> CAN-008 | B11: Akhil Chavan | C11: Edwin | D11: 9948536523 | E11: Bartender | F11: FOH | G11: 25k | H11: 30k | I11: Hyderabad | J11: Hyderabad | K11: Male | L11: Hotel Management | M11: More than 2 Years | N11: Indeed | R11: Akhil Chavan.pdf | S11: 46105 | T11: 46105 | U11: Izumi | W11: Bar Lead | Z11: Kolkata
A12: =IF(B12="","","CAN-"&TEXT(9,"000")) -> CAN-009 | B12: Saurabh Vegurlekar | C12: Edwin | D12: 8369205538 | E12: Head Chef | F12: BOH | G12: 94k | H12: 1LPM | I12: Mumbai | J12: Mumbai | K12: Male | L12: Hotel Management | M12: More than 2 Years | N12: Reference from Candidate | R12: Saurabh V Resume.pdf | S12: 46105 | W12: Bar Manager | Z12: Ahmedabad
A13: =IF(B13="","","CAN-"&TEXT(10,"000")) -> CAN-010 | B13: Mousumi Behera | C13: Edwin | D13: 9635739447 | E13: GRE | F13: BOH | G13: 25k | H13: 27k | I13: Mumbai | J13: Mumbai | K13: Female | L13: Graduate | M13: 6 months-1 year | N13: Reference from Candidate | W13: Bar Supervisor | Z13: Jaipur
A14: =IF(B14="","","CAN-"&TEXT(11,"000")) -> CAN-011 | B14: Moin Pawar | C14: Mohit | D14: 8779074429 | E14: Barista | G14: 18k | H14: 22k | I14: Mumbai | J14: Wasala | K14: Male | L14: HSC | M14: More than 2 years | N14: Reference from Candidate | R14: Moidin Resume-1.pdf | S14: 46106 | U14: Blondie | W14: Barback | Z14: Other
A15: =IF(B15="","","CAN-"&TEXT(12,"000")) -> CAN-012 | B15: Rohan Vagale | C15: Mohit | D15: 7208748204 | E15: Sales | H15: 80k | I15: Mumbai | J15: Other | K15: Male | L15: Hotel Management | M15: More than 2 years | N15: Reference from Candidate | R15: Rohan Vajale Updated CV.pdf | S15: 46106 | W15: Barista
A16: =IF(B16="","","CAN-"&TEXT(13,"000")) -> CAN-013 | B16: Aakash Pandey | C16: Hardik | E16: RM | F16: FOH | G16: 35k | H16: 45k | I16: Goa | K16: Male | L16: Hospitality Graduate | M16: More than 2 years | N16: LinkedIn | S16: 46104 | U16: Milagro (SLH) | W16: Barista Head
A17: =IF(B17="","","CAN-"&TEXT(14,"000")) -> CAN-014 | B17: Farhan | C17: Edwin | E17: Senior CDP | F17: Bartender | G17: 20k | I17: Pune | N17: LinkedIn | S17: 46101 | U17: Slink and Bardot | V17: Blondie | W17: Barista Trainer
A18: =IF(B18="","","CAN-"&TEXT(ROW()-3,"000")) -> CAN-015 | B18: Sandarbh Vishwakarma | C18: Hardik | D18: 7491 973 455 | E18: Head Chef | F18: HeadChef | G18: 110k | H18: 120k | I18: Mumbai | K18: Male | L18: Hospitality Graduate | M18: More than 2 Years | N18: LinkedIn | R18: Sandarbh vishwa europass cv (1).pdf | S18: 46104 | U18: Speciality | V18: Circa 11 | W18: Bartender
A19: =IF(B19="","","CAN-"&TEXT(ROW()-3,"000")) -> CAN-016 | B19: Vinay Nair | C19: Aakash | D19: 9004275980 | E19: Commi | F19: Commi 1/2 | I19: Mumbai | J19: TIlak Nagar | K19: Male | L19: Culinary Graduate | M19: 1-2 years | N19: WhatsApp | R19: Vinay Nair CV_SSW.pdf | S19: 46104 | U19: Donmai | V19: CocoCart | W19: CDP
A20: =IF(B20="","","CAN-"&TEXT(ROW()-3,"000")) -> CAN-017 | B20: Aaghaz Khan | C20: Hardik | D20: 70458 96269 | E20: Head Chef | F20: HeadChef | G20: 120k | H20: 150k | I20: Mumbai | J20: western line | K20: Male | L20: Hotel Management | M20: More than 2 years | N20: LinkedIn | R20: Aaghaz Khan.pdf | S20: 46104 | T20: 46099 | U20: EDD | V20: DU Hospitality | W20: CRM
A21: =IF(B21="","","CAN-"&TEXT(ROW()-3,"000")) -> CAN-018 | B21: Laxman Singh | C21: Hardik | D21: 91376 88461 | E21: Senior Bartender | F21: Bar Sup | G21: 26k | H21: 28k | I21: Mumbai | J21: Other | K21: Male | L21: Hotel Management | M21: More than 2 years | N21: LinkedIn | R21: DOC-20260306-WA0007..docx | S21: 46104 | T21: 46099 | U21: La Loca Maria | V21: Diva | W21: Cafe Manager
A22: =IF(B22="","","CAN-"&TEXT(ROW()-3,"000")) -> CAN-019 | B22: Ajay Kumar Siotra | C22: Hardik | D22: 7006197770 | E22: Head Chef | F22: Head Chef | G22: 110k | H22: 130k | I22: Delhi | J22: Other | K22: Male | L22: Hotel Management | M22: More than 2 years | N22: LinkedIn | R22: ajay kumar cv brand chef.pdf | S22: 46104 | T22: 46106 | U22: Milagro (SLH) | V22: Donmai | W22: Cafe Supervisor
A23: =IF(B23="","","CAN-"&TEXT(20,"000")) -> CAN-020 | B23: Gaurav Renuse | C23: Aakash | D23: 8975185523 | E23: F&B Associate | F23: F&B Associate | I23: Pune | J23: Other | K23: Male | L23: Hotel Management | M23: More than 2 years | N23: LinkedIn | Q23: Need to speak to him | R23: resume 4.docx.pdf | S23: 46104 | V23: Doppler | W23: Captain
A24: =IF(B24="","","CAN-"&TEXT(21,"000")) -> CAN-021 | B24: Hitiksha Jadhav | C24: Manu | D24: 703913704 | E24: Asst Cafe Manager | G24: 30k | H24: 35k | I24: Mumbai | J24: Malad | K24: Female | L24: Graduate | M24: More than 2 years | N24: Reference from Candidate | R24: Simple Professional CV Resume_20241125_205305_0000 (2).pdf | S24: 46104 | U24: Blondie | V24: Dough and Joe | W24: Cashier
A25: =IF(B25="","","CAN-"&TEXT(22,"000")) -> CAN-022 | B25: Atish Bhalera | C25: Aakash | D25: 90826 66795 | E25: Kitchen Helper | F25: Team member | I25: Mumbai | J25: Panvel | K25: Male | L25: 12th Pass | M25: 0-6 Months | N25: Indeed | Q25: Went for training, salary offered was too low | R25: CVAtishBhalerao.pdf | S25: 46104 | T25: 46105 | U25: HNH Salad | V25: EDD | W25: Chef
A26: =IF(B26="","","CAN-"&TEXT(23,"000")) -> CAN-023 | B26: Raushan Kumar | C26: Hardik | E26: Captain | F26: FOH | G26: 22k | H26: 24k | I26: Goa | J26: Other | K26: Male | L26: Hospitality Graduate | M26: More than 2 years | N26: LinkedIn | Q26: Sent to client. | S26: 46104 | T26: 46105 | U26: Milagro (SLH) | V26: FHPL | W26: Commi
A27: =IF(B27="","","CAN-"&TEXT(24,"000")) -> CAN-024 | B27: Omkar Shinde | C27: Aakash | D27: 9152070753 | E27: Senior Barista | F27: Barista | G27: 25k | I27: Mumbai | J27: Chunabhatti | K27: Male | L27: Diploma | M27: More than 2 years | N27: Indeed | R27: CV_Omkar Shinde.pdf | S27: 46105 | U27: Blondie | V27: Flavour Pots | W27: Commi 1
A28: =IF(B28="","","CAN-"&TEXT(25,"000")) -> CAN-025 | B28: Aditi Zaware | C28: Aakash | D28: 9226378468 | E28: Kitchen Helper | F28: Team member | I28: Mumbai | J28: Cuffe Parade | K28: Female | L28: 12th Pass | M28: 0-6 Months | N28: Other | R28: Aditi Zaware_Resume_Apna.pdf | S28: 46105 | V28: Food Square | W28: Commi 2
A29: =IF(B29="","","CAN-"&TEXT(26,"000")) -> CAN-026 | B29: SHREYA DARWATKAR | C29: Aakash | D29: 9930534577 | E29: Commi | F29: Conti/ Garde manger | G29: 21k | I29: Mumbai | J29: Lower Parel | K29: Female | L29: Hotel management | M29: 6 months-1 year | N29: LinkedIn | R29: Shreya Darwatkar Resume.pdf | S29: 46105 | V29: Foodmatters | W29: Commi 3
A30: =IF(B30="","","CAN-"&TEXT(27,"000")) -> CAN-027 | B30: NENGBOI HAOKIP | C30: Aakash | D30: 8794512436 | E30: Hostess | F30: Hostess | G30: 25k++ | I30: Mumbai | K30: Female | L30: Diploma | M30: More than 2 years | N30: LinkedIn | R30: Nengboi Haokip.pdf | S30: 46105 | U30: Blondie | V30: Ghostkitchens | W30: Community Manager
A31: =IF(B31="","","CAN-"&TEXT(28,"000")) -> CAN-028 | B31: Vikash Kumar | C31: Aakash | D31: 6200467250 | E31: Captain | F31: Captain | G31: 22k | I31: Other | K31: Male | L31: Hotel management | M31: More than 2 years | N31: WhatsApp | Q31: Currently working in Ajmer | R31: DOC-20250502-WA0004..docx | S31: 46105 | U31: Doppler | V31: Gupta Brands | W31: Content Strategist
A32: =IF(B32="","","CAN-"&TEXT(29,"000")) -> CAN-029 | B32: Aquib Fayaz | C32: Aakash | D32: 9149787850 | E32: Barista | F32: barista | G32: 20k | I32: Delhi | K32: Male | L32: Graduate | M32: More than 2 years | N32: Indeed | R32: CVAAQIBFAYAZ.pdf | S32: 46105 | U32: Doppler | V32: Huddle and Score | W32: Counter Sales
A33: =IF(B33="","","CAN-"&TEXT(30,"000")) -> CAN-030 | B33: Rushikesh Chavan | C33: Aakash | D33: 8689885539 | E33: Junior Sous Chef | F33: Sous chef | G33: 50k++ | I33: Mumbai | K33: Male | L33: Hotel management | M33: More than 2 years | N33: Reference from Candidate | P33: Worked in Naar, Masque, HOM | R33: CV_2026032320525728.pdf | S33: 46105 | U33: Bare | V33: Hummingtree | W33: DCDP
A34: =IF(B34="","","CAN-"&TEXT(31,"000")) -> CAN-031 | B34: Mahinoor Sayyed | C34: Aakash | D34: 8291034856 | E34: Kitchen Helper | F34: Team member | G34: 20k | I34: Mumbai | J34: Byculla | K34: Female | L34: 12th Pass | M34: More than 2 years | N34: Other | R34: CV_Mahinoor.pdf | S34: 46105 | U34: Greengains | V34: Hunger Inc | W34: Data Analyst
A35: =IF(B35="","","CAN-"&TEXT(32,"000")) -> CAN-032 | B35: Firoj Khan | C35: Manu | D35: 77268 50299 | E35: Captain | F35: Captain | G35: 20k | H35: 25k | I35: Jaipur | K35: Male | L35: Hotel Management | M35: More than 2 years | N35: Reference from Candidate | R35: firoz_F&B_Resume_(2).pdf | S35: 46106 | V35: Idoru | W35: Director of Operations
A36: =IF(B36="","","CAN-"&TEXT(33,"000")) -> CAN-033 | B36: Aarti Jaiswar | C36: Edwin | D36: 8879194006 | E36: Senior GRE | G36: 24k | H36: 38k | I36: Mumbai | J36: Santacruz | K36: Male | L36: Graduate | M36: More than 2 years | N36: Reference from Candidate | R36: Aarti Jaiswar.pdf | S36: 46106 | U36: Izumi | V36: Ikai | W36: Duty Manager
A37: =IF(B37="","","CAN-"&TEXT(34,"000")) -> CAN-034 | B37: Utkarsh | C37: Hardik | D37: 7709783625 | E37: Steward | F37: FOH | G37: 14k | H37: 18k | I37: Mumbai | J37: Naigoan | K37: Male | L37: Hospitality Graduate | M37: More than 2 years | N37: LinkedIn | S37: 46106 | T37: 46108 | U37: Foodmatters | V37: Izumi | W37: EA
A38: =IF(B38="","","CAN-"&TEXT(35,"000")) -> CAN-035 | B38: Surendra Singh | C38: Manu | D38: 7455 999 377 | E38: captain | F38: FOH | G38: 22k | H38: 25k | I38: Delhi | K38: Male | L38: Graduate | M38: More than 2 Years | N38: Reference from Candidate | R38: ResumeSurendarSingh.pdf | V38: Izumi - GOA | W38: Executive Chef
A39: =IF(B39="","","CAN-"&TEXT(36,"000")) -> CAN-036 | B39: Indra Sunari | C39: Hardik | D39: 70578 87947 | E39: Executive Chef | F39: BOH | G39: 82k | H39: 90k | I39: Delhi | J39: Other | K39: Male | L39: Hospitality Graduate | M39: More than 2 years | N39: LinkedIn | S39: 46106 | T39: 46108 | U39: NIKO | V39: Kaia | W39: F&B Associate
A40: =IF(B40="","","CAN-"&TEXT(37,"000")) -> CAN-037 | B40: Imli Longchari | C40: Edwin | D40: 9819862357 | E40: Senior Bartender | F40: FOH | G40: 25k | H40: 35k | I40: Hyderabad | J40: Goa | K40: Male | L40: Graduate | M40: More than 2 years | N40: Indeed | R40: Imliakum Longchari.pdf | S40: 46106 | T40: 46107 | U40: Izumi | V40: Kohinoor Group | W40: F&B Controller
...

Sheet Client Tracker
A1: 📋 CLIENT TRACKER
A2: SELECT CLIENT → | C2: Bare | D2: 👆 Select a client → table auto-fills. Share this Google Sheet link (view only) with your client.
A4: =IF($C$2="","← Select a client from the dropdown to view their candidates","Showing "&COUNTIF('Candidate Database'!U4:U998,$C$2)&" candidate(s) for: "&$C$2) -> Showing 2 candidate(s) for: Bare | I4: Interview Pending | J4: ABNAH
A5: # | B5: Candidate Name | C5: Role | D5: Current Salary | E5: Expected Salary | F5: CV Link | G5: Binge Screening Remarks | H5: Status | I5: Result Pending | J5: Abhinav Immigration
A6: =IF(COUNTIF('Candidate Database'!U$4:U$998,$C$2)>=1,1,"") -> 1 | B6: =IFERROR(__xludf.DUMMYFUNCTION("IFERROR(INDEX(FILTER('Candidate Database'!B$4:B$998,'Candidate Database'!U$4:U$998=$C$2),1),"""")"),"Rushikesh Chavan") -> Rushikesh Chavan | C6: =IFERROR(__xludf.DUMMYFUNCTION("IFERROR(INDEX(FILTER('Candidate Database'!E$4:E$998,'Candidate Database'!U$4:U$998=$C$2),1),"""")"),"Junior Sous Chef") -> Junior Sous Chef | D6: =IFERROR(__xludf.DUMMYFUNCTION("IFERROR(INDEX(FILTER('Candidate Database'!G$4:G$998,'Candidate Database'!U$4:U$998=$C$2),1),"""")"),"50k++") -> 50k++ | E6: =IFERROR(__xludf.DUMMYFUNCTION("IFERROR(INDEX(FILTER('Candidate Database'!H$4:H$998,'Candidate Database'!U$4:U$998=$C$2),1),"""")"),"") | F6: =IFERROR(__xludf.DUMMYFUNCTION("IFERROR(INDEX(FILTER('Candidate Database'!R$4:R$998,'Candidate Database'!U$4:U$998=$C$2),1),"""")"),"CV_2026032320525728.pdf") -> CV_2026032320525728.pdf | G6: =IFERROR(__xludf.DUMMYFUNCTION("IFERROR(INDEX(FILTER('Candidate Database'!P$4:P$998,'Candidate Database'!U$4:U$998=$C$2),1),"""")"),"Worked in Naar, Masque, HOM") -> Worked in Naar, Masque, HOM | H6: Offer Pending | I6: Offer Pending | J6: Adarsh Sweets
A7: =IF(COUNTIF('Candidate Database'!U$4:U$998,$C$2)>=2,2,"") -> 2 | B7: =IFERROR(__xludf.DUMMYFUNCTION("IFERROR(INDEX(FILTER('Candidate Database'!B$4:B$998,'Candidate Database'!U$4:U$998=$C$2),2),"""")"),"Nikhil Tambe") -> Nikhil Tambe | C7: =IFERROR(__xludf.DUMMYFUNCTION("IFERROR(INDEX(FILTER('Candidate Database'!E$4:E$998,'Candidate Database'!U$4:U$998=$C$2),2),"""")"),"ARM") -> ARM | D7: =IFERROR(__xludf.DUMMYFUNCTION("IFERROR(INDEX(FILTER('Candidate Database'!G$4:G$998,'Candidate Database'!U$4:U$998=$C$2),2),"""")"),"35k") -> 35k | E7: =IFERROR(__xludf.DUMMYFUNCTION("IFERROR(INDEX(FILTER('Candidate Database'!H$4:H$998,'Candidate Database'!U$4:U$998=$C$2),2),"""")"),"45k") -> 45k | F7: =IFERROR(__xludf.DUMMYFUNCTION("IFERROR(INDEX(FILTER('Candidate Database'!R$4:R$998,'Candidate Database'!U$4:U$998=$C$2),2),"""")"),"Nikhil Tambe Resume.pdf") -> Nikhil Tambe Resume.pdf | G7: =IFERROR(__xludf.DUMMYFUNCTION("IFERROR(INDEX(FILTER('Candidate Database'!P$4:P$998,'Candidate Database'!U$4:U$998=$C$2),2),"""")"),"") | H7: Interview Pending | I7: Candidate Rejected | J7: Agarwal Biryani
A8: =IF(COUNTIF('Candidate Database'!U$4:U$998,$C$2)>=3,3,"") | B8: =IFERROR(__xludf.DUMMYFUNCTION("IFERROR(INDEX(FILTER('Candidate Database'!B$4:B$998,'Candidate Database'!U$4:U$998=$C$2),3),"""")"),"") | C8: =IFERROR(__xludf.DUMMYFUNCTION("IFERROR(INDEX(FILTER('Candidate Database'!E$4:E$998,'Candidate Database'!U$4:U$998=$C$2),3),"""")"),"") | D8: =IFERROR(__xludf.DUMMYFUNCTION("IFERROR(INDEX(FILTER('Candidate Database'!G$4:G$998,'Candidate Database'!U$4:U$998=$C$2),3),"""")"),"") | E8: =IFERROR(__xludf.DUMMYFUNCTION("IFERROR(INDEX(FILTER('Candidate Database'!H$4:H$998,'Candidate Database'!U$4:U$998=$C$2),3),"""")"),"") | F8: =IFERROR(__xludf.DUMMYFUNCTION("IFERROR(INDEX(FILTER('Candidate Database'!R$4:R$998,'Candidate Database'!U$4:U$998=$C$2),3),"""")"),"") | G8: =IFERROR(__xludf.DUMMYFUNCTION("IFERROR(INDEX(FILTER('Candidate Database'!P$4:P$998,'Candidate Database'!U$4:U$998=$C$2),3),"""")"),"") | H8: Interview Pending | I8: Candidate Dropped | J8: All in
A9: =IF(COUNTIF('Candidate Database'!U$4:U$998,$C$2)>=4,4,"") | B9: =IFERROR(__xludf.DUMMYFUNCTION("IFERROR(INDEX(FILTER('Candidate Database'!B$4:B$998,'Candidate Database'!U$4:U$998=$C$2),4),"""")"),"") | C9: =IFERROR(__xludf.DUMMYFUNCTION("IFERROR(INDEX(FILTER('Candidate Database'!E$4:E$998,'Candidate Database'!U$4:U$998=$C$2),4),"""")"),"") | D9: =IFERROR(__xludf.DUMMYFUNCTION("IFERROR(INDEX(FILTER('Candidate Database'!G$4:G$998,'Candidate Database'!U$4:U$998=$C$2),4),"""")"),"") | E9: =IFERROR(__xludf.DUMMYFUNCTION("IFERROR(INDEX(FILTER('Candidate Database'!H$4:H$998,'Candidate Database'!U$4:U$998=$C$2),4),"""")"),"") | F9: =IFERROR(__xludf.DUMMYFUNCTION("IFERROR(INDEX(FILTER('Candidate Database'!R$4:R$998,'Candidate Database'!U$4:U$998=$C$2),4),"""")"),"") | G9: =IFERROR(__xludf.DUMMYFUNCTION("IFERROR(INDEX(FILTER('Candidate Database'!P$4:P$998,'Candidate Database'!U$4:U$998=$C$2),4),"""")"),"") | H9: Interview Pending | J9: Aria Communication
A10: =IF(COUNTIF('Candidate Database'!U$4:U$998,$C$2)>=5,5,"") | B10: =IFERROR(__xludf.DUMMYFUNCTION("IFERROR(INDEX(FILTER('Candidate Database'!B$4:B$998,'Candidate Database'!U$4:U$998=$C$2),5),"""")"),"") | C10: =IFERROR(__xludf.DUMMYFUNCTION("IFERROR(INDEX(FILTER('Candidate Database'!E$4:E$998,'Candidate Database'!U$4:U$998=$C$2),5),"""")"),"") | D10: =IFERROR(__xludf.DUMMYFUNCTION("IFERROR(INDEX(FILTER('Candidate Database'!G$4:G$998,'Candidate Database'!U$4:U$998=$C$2),5),"""")"),"") | E10: =IFERROR(__xludf.DUMMYFUNCTION("IFERROR(INDEX(FILTER('Candidate Database'!H$4:H$998,'Candidate Database'!U$4:U$998=$C$2),5),"""")"),"") | F10: =IFERROR(__xludf.DUMMYFUNCTION("IFERROR(INDEX(FILTER('Candidate Database'!R$4:R$998,'Candidate Database'!U$4:U$998=$C$2),5),"""")"),"") | G10: =IFERROR(__xludf.DUMMYFUNCTION("IFERROR(INDEX(FILTER('Candidate Database'!P$4:P$998,'Candidate Database'!U$4:U$998=$C$2),5),"""")"),"") | H10: Interview Pending | J10: Atmosphere
A11: =IF(COUNTIF('Candidate Database'!U$4:U$998,$C$2)>=6,6,"") | B11: =IFERROR(__xludf.DUMMYFUNCTION("IFERROR(INDEX(FILTER('Candidate Database'!B$4:B$998,'Candidate Database'!U$4:U$998=$C$2),6),"""")"),"") | C11: =IFERROR(__xludf.DUMMYFUNCTION("IFERROR(INDEX(FILTER('Candidate Database'!E$4:E$998,'Candidate Database'!U$4:U$998=$C$2),6),"""")"),"") | D11: =IFERROR(__xludf.DUMMYFUNCTION("IFERROR(INDEX(FILTER('Candidate Database'!G$4:G$998,'Candidate Database'!U$4:U$998=$C$2),6),"""")"),"") | E11: =IFERROR(__xludf.DUMMYFUNCTION("IFERROR(INDEX(FILTER('Candidate Database'!H$4:H$998,'Candidate Database'!U$4:U$998=$C$2),6),"""")"),"") | F11: =IFERROR(__xludf.DUMMYFUNCTION("IFERROR(INDEX(FILTER('Candidate Database'!R$4:R$998,'Candidate Database'!U$4:U$998=$C$2),6),"""")"),"") | G11: =IFERROR(__xludf.DUMMYFUNCTION("IFERROR(INDEX(FILTER('Candidate Database'!P$4:P$998,'Candidate Database'!U$4:U$998=$C$2),6),"""")"),"") | H11: Interview Pending | J11: August Café
A12: =IF(COUNTIF('Candidate Database'!U$4:U$998,$C$2)>=7,7,"") | B12: =IFERROR(__xludf.DUMMYFUNCTION("IFERROR(INDEX(FILTER('Candidate Database'!B$4:B$998,'Candidate Database'!U$4:U$998=$C$2),7),"""")"),"") | C12: =IFERROR(__xludf.DUMMYFUNCTION("IFERROR(INDEX(FILTER('Candidate Database'!E$4:E$998,'Candidate Database'!U$4:U$998=$C$2),7),"""")"),"") | D12: =IFERROR(__xludf.DUMMYFUNCTION("IFERROR(INDEX(FILTER('Candidate Database'!G$4:G$998,'Candidate Database'!U$4:U$998=$C$2),7),"""")"),"") | E12: =IFERROR(__xludf.DUMMYFUNCTION("IFERROR(INDEX(FILTER('Candidate Database'!H$4:H$998,'Candidate Database'!U$4:U$998=$C$2),7),"""")"),"") | F12: =IFERROR(__xludf.DUMMYFUNCTION("IFERROR(INDEX(FILTER('Candidate Database'!R$4:R$998,'Candidate Database'!U$4:U$998=$C$2),7),"""")"),"") | G12: =IFERROR(__xludf.DUMMYFUNCTION("IFERROR(INDEX(FILTER('Candidate Database'!P$4:P$998,'Candidate Database'!U$4:U$998=$C$2),7),"""")"),"") | H12: Interview Pending | J12: Aures hospitality
A13: =IF(COUNTIF('Candidate Database'!U$4:U$998,$C$2)>=8,8,"") | B13: =IFERROR(__xludf.DUMMYFUNCTION("IFERROR(INDEX(FILTER('Candidate Database'!B$4:B$998,'Candidate Database'!U$4:U$998=$C$2),8),"""")"),"") | C13: =IFERROR(__xludf.DUMMYFUNCTION("IFERROR(INDEX(FILTER('Candidate Database'!E$4:E$998,'Candidate Database'!U$4:U$998=$C$2),8),"""")"),"") | D13: =IFERROR(__xludf.DUMMYFUNCTION("IFERROR(INDEX(FILTER('Candidate Database'!G$4:G$998,'Candidate Database'!U$4:U$998=$C$2),8),"""")"),"") | E13: =IFERROR(__xludf.DUMMYFUNCTION("IFERROR(INDEX(FILTER('Candidate Database'!H$4:H$998,'Candidate Database'!U$4:U$998=$C$2),8),"""")"),"") | F13: =IFERROR(__xludf.DUMMYFUNCTION("IFERROR(INDEX(FILTER('Candidate Database'!R$4:R$998,'Candidate Database'!U$4:U$998=$C$2),8),"""")"),"") | G13: =IFERROR(__xludf.DUMMYFUNCTION("IFERROR(INDEX(FILTER('Candidate Database'!P$4:P$998,'Candidate Database'!U$4:U$998=$C$2),8),"""")"),"") | J13: BB
A14: =IF(COUNTIF('Candidate Database'!U$4:U$998,$C$2)>=9,9,"") | B14: =IFERROR(__xludf.DUMMYFUNCTION("IFERROR(INDEX(FILTER('Candidate Database'!B$4:B$998,'Candidate Database'!U$4:U$998=$C$2),9),"""")"),"") | C14: =IFERROR(__xludf.DUMMYFUNCTION("IFERROR(INDEX(FILTER('Candidate Database'!E$4:E$998,'Candidate Database'!U$4:U$998=$C$2),9),"""")"),"") | D14: =IFERROR(__xludf.DUMMYFUNCTION("IFERROR(INDEX(FILTER('Candidate Database'!G$4:G$998,'Candidate Database'!U$4:U$998=$C$2),9),"""")"),"") | E14: =IFERROR(__xludf.DUMMYFUNCTION("IFERROR(INDEX(FILTER('Candidate Database'!H$4:H$998,'Candidate Database'!U$4:U$998=$C$2),9),"""")"),"") | F14: =IFERROR(__xludf.DUMMYFUNCTION("IFERROR(INDEX(FILTER('Candidate Database'!R$4:R$998,'Candidate Database'!U$4:U$998=$C$2),9),"""")"),"") | G14: =IFERROR(__xludf.DUMMYFUNCTION("IFERROR(INDEX(FILTER('Candidate Database'!P$4:P$998,'Candidate Database'!U$4:U$998=$C$2),9),"""")"),"") | H14: Interview Pending | J14: BTC
A15: =IF(COUNTIF('Candidate Database'!U$4:U$998,$C$2)>=10,10,"") | B15: =IFERROR(__xludf.DUMMYFUNCTION("IFERROR(INDEX(FILTER('Candidate Database'!B$4:B$998,'Candidate Database'!U$4:U$998=$C$2),10),"""")"),"") | C15: =IFERROR(__xludf.DUMMYFUNCTION("IFERROR(INDEX(FILTER('Candidate Database'!E$4:E$998,'Candidate Database'!U$4:U$998=$C$2),10),"""")"),"") | D15: =IFERROR(__xludf.DUMMYFUNCTION("IFERROR(INDEX(FILTER('Candidate Database'!G$4:G$998,'Candidate Database'!U$4:U$998=$C$2),10),"""")"),"") | E15: =IFERROR(__xludf.DUMMYFUNCTION("IFERROR(INDEX(FILTER('Candidate Database'!H$4:H$998,'Candidate Database'!U$4:U$998=$C$2),10),"""")"),"") | F15: =IFERROR(__xludf.DUMMYFUNCTION("IFERROR(INDEX(FILTER('Candidate Database'!R$4:R$998,'Candidate Database'!U$4:U$998=$C$2),10),"""")"),"") | G15: =IFERROR(__xludf.DUMMYFUNCTION("IFERROR(INDEX(FILTER('Candidate Database'!P$4:P$998,'Candidate Database'!U$4:U$998=$C$2),10),"""")"),"") | J15: Baesic Fit
A16: =IF(COUNTIF('Candidate Database'!U$4:U$998,$C$2)>=11,11,"") | B16: =IFERROR(__xludf.DUMMYFUNCTION("IFERROR(INDEX(FILTER('Candidate Database'!B$4:B$998,'Candidate Database'!U$4:U$998=$C$2),11),"""")"),"") | C16: =IFERROR(__xludf.DUMMYFUNCTION("IFERROR(INDEX(FILTER('Candidate Database'!E$4:E$998,'Candidate Database'!U$4:U$998=$C$2),11),"""")"),"") | D16: =IFERROR(__xludf.DUMMYFUNCTION("IFERROR(INDEX(FILTER('Candidate Database'!G$4:G$998,'Candidate Database'!U$4:U$998=$C$2),11),"""")"),"") | E16: =IFERROR(__xludf.DUMMYFUNCTION("IFERROR(INDEX(FILTER('Candidate Database'!H$4:H$998,'Candidate Database'!U$4:U$998=$C$2),11),"""")"),"") | F16: =IFERROR(__xludf.DUMMYFUNCTION("IFERROR(INDEX(FILTER('Candidate Database'!R$4:R$998,'Candidate Database'!U$4:U$998=$C$2),11),"""")"),"") | G16: =IFERROR(__xludf.DUMMYFUNCTION("IFERROR(INDEX(FILTER('Candidate Database'!P$4:P$998,'Candidate Database'!U$4:U$998=$C$2),11),"""")"),"") | J16: Bare
A17: =IF(COUNTIF('Candidate Database'!U$4:U$998,$C$2)>=12,12,"") | B17: =IFERROR(__xludf.DUMMYFUNCTION("IFERROR(INDEX(FILTER('Candidate Database'!B$4:B$998,'Candidate Database'!U$4:U$998=$C$2),12),"""")"),"") | C17: =IFERROR(__xludf.DUMMYFUNCTION("IFERROR(INDEX(FILTER('Candidate Database'!E$4:E$998,'Candidate Database'!U$4:U$998=$C$2),12),"""")"),"") | D17: =IFERROR(__xludf.DUMMYFUNCTION("IFERROR(INDEX(FILTER('Candidate Database'!G$4:G$998,'Candidate Database'!U$4:U$998=$C$2),12),"""")"),"") | E17: =IFERROR(__xludf.DUMMYFUNCTION("IFERROR(INDEX(FILTER('Candidate Database'!H$4:H$998,'Candidate Database'!U$4:U$998=$C$2),12),"""")"),"") | F17: =IFERROR(__xludf.DUMMYFUNCTION("IFERROR(INDEX(FILTER('Candidate Database'!R$4:R$998,'Candidate Database'!U$4:U$998=$C$2),12),"""")"),"") | G17: =IFERROR(__xludf.DUMMYFUNCTION("IFERROR(INDEX(FILTER('Candidate Database'!P$4:P$998,'Candidate Database'!U$4:U$998=$C$2),12),"""")"),"") | J17: Blondie
A18: =IF(COUNTIF('Candidate Database'!U$4:U$998,$C$2)>=13,13,"") | B18: =IFERROR(__xludf.DUMMYFUNCTION("IFERROR(INDEX(FILTER('Candidate Database'!B$4:B$998,'Candidate Database'!U$4:U$998=$C$2),13),"""")"),"") | C18: =IFERROR(__xludf.DUMMYFUNCTION("IFERROR(INDEX(FILTER('Candidate Database'!E$4:E$998,'Candidate Database'!U$4:U$998=$C$2),13),"""")"),"") | D18: =IFERROR(__xludf.DUMMYFUNCTION("IFERROR(INDEX(FILTER('Candidate Database'!G$4:G$998,'Candidate Database'!U$4:U$998=$C$2),13),"""")"),"") | E18: =IFERROR(__xludf.DUMMYFUNCTION("IFERROR(INDEX(FILTER('Candidate Database'!H$4:H$998,'Candidate Database'!U$4:U$998=$C$2),13),"""")"),"") | F18: =IFERROR(__xludf.DUMMYFUNCTION("IFERROR(INDEX(FILTER('Candidate Database'!R$4:R$998,'Candidate Database'!U$4:U$998=$C$2),13),"""")"),"") | G18: =IFERROR(__xludf.DUMMYFUNCTION("IFERROR(INDEX(FILTER('Candidate Database'!P$4:P$998,'Candidate Database'!U$4:U$998=$C$2),13),"""")"),"") | J18: Circa 11
A19: =IF(COUNTIF('Candidate Database'!U$4:U$998,$C$2)>=14,14,"") | B19: =IFERROR(__xludf.DUMMYFUNCTION("IFERROR(INDEX(FILTER('Candidate Database'!B$4:B$998,'Candidate Database'!U$4:U$998=$C$2),14),"""")"),"") | C19: =IFERROR(__xludf.DUMMYFUNCTION("IFERROR(INDEX(FILTER('Candidate Database'!E$4:E$998,'Candidate Database'!U$4:U$998=$C$2),14),"""")"),"") | D19: =IFERROR(__xludf.DUMMYFUNCTION("IFERROR(INDEX(FILTER('Candidate Database'!G$4:G$998,'Candidate Database'!U$4:U$998=$C$2),14),"""")"),"") | E19: =IFERROR(__xludf.DUMMYFUNCTION("IFERROR(INDEX(FILTER('Candidate Database'!H$4:H$998,'Candidate Database'!U$4:U$998=$C$2),14),"""")"),"") | F19: =IFERROR(__xludf.DUMMYFUNCTION("IFERROR(INDEX(FILTER('Candidate Database'!R$4:R$998,'Candidate Database'!U$4:U$998=$C$2),14),"""")"),"") | G19: =IFERROR(__xludf.DUMMYFUNCTION("IFERROR(INDEX(FILTER('Candidate Database'!P$4:P$998,'Candidate Database'!U$4:U$998=$C$2),14),"""")"),"") | J19: CocoCart
A20: =IF(COUNTIF('Candidate Database'!U$4:U$998,$C$2)>=15,15,"") | B20: =IFERROR(__xludf.DUMMYFUNCTION("IFERROR(INDEX(FILTER('Candidate Database'!B$4:B$998,'Candidate Database'!U$4:U$998=$C$2),15),"""")"),"") | C20: =IFERROR(__xludf.DUMMYFUNCTION("IFERROR(INDEX(FILTER('Candidate Database'!E$4:E$998,'Candidate Database'!U$4:U$998=$C$2),15),"""")"),"") | D20: =IFERROR(__xludf.DUMMYFUNCTION("IFERROR(INDEX(FILTER('Candidate Database'!G$4:G$998,'Candidate Database'!U$4:U$998=$C$2),15),"""")"),"") | E20: =IFERROR(__xludf.DUMMYFUNCTION("IFERROR(INDEX(FILTER('Candidate Database'!H$4:H$998,'Candidate Database'!U$4:U$998=$C$2),15),"""")"),"") | F20: =IFERROR(__xludf.DUMMYFUNCTION("IFERROR(INDEX(FILTER('Candidate Database'!R$4:R$998,'Candidate Database'!U$4:U$998=$C$2),15),"""")"),"") | G20: =IFERROR(__xludf.DUMMYFUNCTION("IFERROR(INDEX(FILTER('Candidate Database'!P$4:P$998,'Candidate Database'!U$4:U$998=$C$2),15),"""")"),"") | J20: DU Hospitality
A21: =IF(COUNTIF('Candidate Database'!U$4:U$998,$C$2)>=16,16,"") | B21: =IFERROR(__xludf.DUMMYFUNCTION("IFERROR(INDEX(FILTER('Candidate Database'!B$4:B$998,'Candidate Database'!U$4:U$998=$C$2),16),"""")"),"") | C21: =IFERROR(__xludf.DUMMYFUNCTION("IFERROR(INDEX(FILTER('Candidate Database'!E$4:E$998,'Candidate Database'!U$4:U$998=$C$2),16),"""")"),"") | D21: =IFERROR(__xludf.DUMMYFUNCTION("IFERROR(INDEX(FILTER('Candidate Database'!G$4:G$998,'Candidate Database'!U$4:U$998=$C$2),16),"""")"),"") | E21: =IFERROR(__xludf.DUMMYFUNCTION("IFERROR(INDEX(FILTER('Candidate Database'!H$4:H$998,'Candidate Database'!U$4:U$998=$C$2),16),"""")"),"") | F21: =IFERROR(__xludf.DUMMYFUNCTION("IFERROR(INDEX(FILTER('Candidate Database'!R$4:R$998,'Candidate Database'!U$4:U$998=$C$2),16),"""")"),"") | G21: =IFERROR(__xludf.DUMMYFUNCTION("IFERROR(INDEX(FILTER('Candidate Database'!P$4:P$998,'Candidate Database'!U$4:U$998=$C$2),16),"""")"),"") | J21: Diva
A22: =IF(COUNTIF('Candidate Database'!U$4:U$998,$C$2)>=17,17,"") | B22: =IFERROR(__xludf.DUMMYFUNCTION("IFERROR(INDEX(FILTER('Candidate Database'!B$4:B$998,'Candidate Database'!U$4:U$998=$C$2),17),"""")"),"") | C22: =IFERROR(__xludf.DUMMYFUNCTION("IFERROR(INDEX(FILTER('Candidate Database'!E$4:E$998,'Candidate Database'!U$4:U$998=$C$2),17),"""")"),"") | D22: =IFERROR(__xludf.DUMMYFUNCTION("IFERROR(INDEX(FILTER('Candidate Database'!G$4:G$998,'Candidate Database'!U$4:U$998=$C$2),17),"""")"),"") | E22: =IFERROR(__xludf.DUMMYFUNCTION("IFERROR(INDEX(FILTER('Candidate Database'!H$4:H$998,'Candidate Database'!U$4:U$998=$C$2),17),"""")"),"") | F22: =IFERROR(__xludf.DUMMYFUNCTION("IFERROR(INDEX(FILTER('Candidate Database'!R$4:R$998,'Candidate Database'!U$4:U$998=$C$2),17),"""")"),"") | G22: =IFERROR(__xludf.DUMMYFUNCTION("IFERROR(INDEX(FILTER('Candidate Database'!P$4:P$998,'Candidate Database'!U$4:U$998=$C$2),17),"""")"),"") | J22: Donmai
A23: =IF(COUNTIF('Candidate Database'!U$4:U$998,$C$2)>=18,18,"") | B23: =IFERROR(__xludf.DUMMYFUNCTION("IFERROR(INDEX(FILTER('Candidate Database'!B$4:B$998,'Candidate Database'!U$4:U$998=$C$2),18),"""")"),"") | C23: =IFERROR(__xludf.DUMMYFUNCTION("IFERROR(INDEX(FILTER('Candidate Database'!E$4:E$998,'Candidate Database'!U$4:U$998=$C$2),18),"""")"),"") | D23: =IFERROR(__xludf.DUMMYFUNCTION("IFERROR(INDEX(FILTER('Candidate Database'!G$4:G$998,'Candidate Database'!U$4:U$998=$C$2),18),"""")"),"") | E23: =IFERROR(__xludf.DUMMYFUNCTION("IFERROR(INDEX(FILTER('Candidate Database'!H$4:H$998,'Candidate Database'!U$4:U$998=$C$2),18),"""")"),"") | F23: =IFERROR(__xludf.DUMMYFUNCTION("IFERROR(INDEX(FILTER('Candidate Database'!R$4:R$998,'Candidate Database'!U$4:U$998=$C$2),18),"""")"),"") | G23: =IFERROR(__xludf.DUMMYFUNCTION("IFERROR(INDEX(FILTER('Candidate Database'!P$4:P$998,'Candidate Database'!U$4:U$998=$C$2),18),"""")"),"") | J23: Doppler
A24: =IF(COUNTIF('Candidate Database'!U$4:U$998,$C$2)>=19,19,"") | B24: =IFERROR(__xludf.DUMMYFUNCTION("IFERROR(INDEX(FILTER('Candidate Database'!B$4:B$998,'Candidate Database'!U$4:U$998=$C$2),19),"""")"),"") | C24: =IFERROR(__xludf.DUMMYFUNCTION("IFERROR(INDEX(FILTER('Candidate Database'!E$4:E$998,'Candidate Database'!U$4:U$998=$C$2),19),"""")"),"") | D24: =IFERROR(__xludf.DUMMYFUNCTION("IFERROR(INDEX(FILTER('Candidate Database'!G$4:G$998,'Candidate Database'!U$4:U$998=$C$2),19),"""")"),"") | E24: =IFERROR(__xludf.DUMMYFUNCTION("IFERROR(INDEX(FILTER('Candidate Database'!H$4:H$998,'Candidate Database'!U$4:U$998=$C$2),19),"""")"),"") | F24: =IFERROR(__xludf.DUMMYFUNCTION("IFERROR(INDEX(FILTER('Candidate Database'!R$4:R$998,'Candidate Database'!U$4:U$998=$C$2),19),"""")"),"") | G24: =IFERROR(__xludf.DUMMYFUNCTION("IFERROR(INDEX(FILTER('Candidate Database'!P$4:P$998,'Candidate Database'!U$4:U$998=$C$2),19),"""")"),"") | J24: Dough and Joe
A25: =IF(COUNTIF('Candidate Database'!U$4:U$998,$C$2)>=20,20,"") | B25: =IFERROR(__xludf.DUMMYFUNCTION("IFERROR(INDEX(FILTER('Candidate Database'!B$4:B$998,'Candidate Database'!U$4:U$998=$C$2),20),"""")"),"") | C25: =IFERROR(__xludf.DUMMYFUNCTION("IFERROR(INDEX(FILTER('Candidate Database'!E$4:E$998,'Candidate Database'!U$4:U$998=$C$2),20),"""")"),"") | D25: =IFERROR(__xludf.DUMMYFUNCTION("IFERROR(INDEX(FILTER('Candidate Database'!G$4:G$998,'Candidate Database'!U$4:U$998=$C$2),20),"""")"),"") | E25: =IFERROR(__xludf.DUMMYFUNCTION("IFERROR(INDEX(FILTER('Candidate Database'!H$4:H$998,'Candidate Database'!U$4:U$998=$C$2),20),"""")"),"") | F25: =IFERROR(__xludf.DUMMYFUNCTION("IFERROR(INDEX(FILTER('Candidate Database'!R$4:R$998,'Candidate Database'!U$4:U$998=$C$2),20),"""")"),"") | G25: =IFERROR(__xludf.DUMMYFUNCTION("IFERROR(INDEX(FILTER('Candidate Database'!P$4:P$998,'Candidate Database'!U$4:U$998=$C$2),20),"""")"),"") | J25: EDD
A26: =IF(COUNTIF('Candidate Database'!U$4:U$998,$C$2)>=21,21,"") | B26: =IFERROR(__xludf.DUMMYFUNCTION("IFERROR(INDEX(FILTER('Candidate Database'!B$4:B$998,'Candidate Database'!U$4:U$998=$C$2),21),"""")"),"") | C26: =IFERROR(__xludf.DUMMYFUNCTION("IFERROR(INDEX(FILTER('Candidate Database'!E$4:E$998,'Candidate Database'!U$4:U$998=$C$2),21),"""")"),"") | D26: =IFERROR(__xludf.DUMMYFUNCTION("IFERROR(INDEX(FILTER('Candidate Database'!G$4:G$998,'Candidate Database'!U$4:U$998=$C$2),21),"""")"),"") | E26: =IFERROR(__xludf.DUMMYFUNCTION("IFERROR(INDEX(FILTER('Candidate Database'!H$4:H$998,'Candidate Database'!U$4:U$998=$C$2),21),"""")"),"") | F26: =IFERROR(__xludf.DUMMYFUNCTION("IFERROR(INDEX(FILTER('Candidate Database'!R$4:R$998,'Candidate Database'!U$4:U$998=$C$2),21),"""")"),"") | G26: =IFERROR(__xludf.DUMMYFUNCTION("IFERROR(INDEX(FILTER('Candidate Database'!P$4:P$998,'Candidate Database'!U$4:U$998=$C$2),21),"""")"),"") | J26: FHPL
A27: =IF(COUNTIF('Candidate Database'!U$4:U$998,$C$2)>=22,22,"") | B27: =IFERROR(__xludf.DUMMYFUNCTION("IFERROR(INDEX(FILTER('Candidate Database'!B$4:B$998,'Candidate Database'!U$4:U$998=$C$2),22),"""")"),"") | C27: =IFERROR(__xludf.DUMMYFUNCTION("IFERROR(INDEX(FILTER('Candidate Database'!E$4:E$998,'Candidate Database'!U$4:U$998=$C$2),22),"""")"),"") | D27: =IFERROR(__xludf.DUMMYFUNCTION("IFERROR(INDEX(FILTER('Candidate Database'!G$4:G$998,'Candidate Database'!U$4:U$998=$C$2),22),"""")"),"") | E27: =IFERROR(__xludf.DUMMYFUNCTION("IFERROR(INDEX(FILTER('Candidate Database'!H$4:H$998,'Candidate Database'!U$4:U$998=$C$2),22),"""")"),"") | F27: =IFERROR(__xludf.DUMMYFUNCTION("IFERROR(INDEX(FILTER('Candidate Database'!R$4:R$998,'Candidate Database'!U$4:U$998=$C$2),22),"""")"),"") | G27: =IFERROR(__xludf.DUMMYFUNCTION("IFERROR(INDEX(FILTER('Candidate Database'!P$4:P$998,'Candidate Database'!U$4:U$998=$C$2),22),"""")"),"") | J27: Flavour Pots
A28: =IF(COUNTIF('Candidate Database'!U$4:U$998,$C$2)>=23,23,"") | B28: =IFERROR(__xludf.DUMMYFUNCTION("IFERROR(INDEX(FILTER('Candidate Database'!B$4:B$998,'Candidate Database'!U$4:U$998=$C$2),23),"""")"),"") | C28: =IFERROR(__xludf.DUMMYFUNCTION("IFERROR(INDEX(FILTER('Candidate Database'!E$4:E$998,'Candidate Database'!U$4:U$998=$C$2),23),"""")"),"") | D28: =IFERROR(__xludf.DUMMYFUNCTION("IFERROR(INDEX(FILTER('Candidate Database'!G$4:G$998,'Candidate Database'!U$4:U$998=$C$2),23),"""")"),"") | E28: =IFERROR(__xludf.DUMMYFUNCTION("IFERROR(INDEX(FILTER('Candidate Database'!H$4:H$998,'Candidate Database'!U$4:U$998=$C$2),23),"""")"),"") | F28: =IFERROR(__xludf.DUMMYFUNCTION("IFERROR(INDEX(FILTER('Candidate Database'!R$4:R$998,'Candidate Database'!U$4:U$998=$C$2),23),"""")"),"") | G28: =IFERROR(__xludf.DUMMYFUNCTION("IFERROR(INDEX(FILTER('Candidate Database'!P$4:P$998,'Candidate Database'!U$4:U$998=$C$2),23),"""")"),"") | J28: Food Square
A29: =IF(COUNTIF('Candidate Database'!U$4:U$998,$C$2)>=24,24,"") | B29: =IFERROR(__xludf.DUMMYFUNCTION("IFERROR(INDEX(FILTER('Candidate Database'!B$4:B$998,'Candidate Database'!U$4:U$998=$C$2),24),"""")"),"") | C29: =IFERROR(__xludf.DUMMYFUNCTION("IFERROR(INDEX(FILTER('Candidate Database'!E$4:E$998,'Candidate Database'!U$4:U$998=$C$2),24),"""")"),"") | D29: =IFERROR(__xludf.DUMMYFUNCTION("IFERROR(INDEX(FILTER('Candidate Database'!G$4:G$998,'Candidate Database'!U$4:U$998=$C$2),24),"""")"),"") | E29: =IFERROR(__xludf.DUMMYFUNCTION("IFERROR(INDEX(FILTER('Candidate Database'!H$4:H$998,'Candidate Database'!U$4:U$998=$C$2),24),"""")"),"") | F29: =IFERROR(__xludf.DUMMYFUNCTION("IFERROR(INDEX(FILTER('Candidate Database'!R$4:R$998,'Candidate Database'!U$4:U$998=$C$2),24),"""")"),"") | G29: =IFERROR(__xludf.DUMMYFUNCTION("IFERROR(INDEX(FILTER('Candidate Database'!P$4:P$998,'Candidate Database'!U$4:U$998=$C$2),24),"""")"),"") | J29: Foodmatters
A30: =IF(COUNTIF('Candidate Database'!U$4:U$998,$C$2)>=25,25,"") | B30: =IFERROR(__xludf.DUMMYFUNCTION("IFERROR(INDEX(FILTER('Candidate Database'!B$4:B$998,'Candidate Database'!U$4:U$998=$C$2),25),"""")"),"") | C30: =IFERROR(__xludf.DUMMYFUNCTION("IFERROR(INDEX(FILTER('Candidate Database'!E$4:E$998,'Candidate Database'!U$4:U$998=$C$2),25),"""")"),"") | D30: =IFERROR(__xludf.DUMMYFUNCTION("IFERROR(INDEX(FILTER('Candidate Database'!G$4:G$998,'Candidate Database'!U$4:U$998=$C$2),25),"""")"),"") | E30: =IFERROR(__xludf.DUMMYFUNCTION("IFERROR(INDEX(FILTER('Candidate Database'!H$4:H$998,'Candidate Database'!U$4:U$998=$C$2),25),"""")"),"") | F30: =IFERROR(__xludf.DUMMYFUNCTION("IFERROR(INDEX(FILTER('Candidate Database'!R$4:R$998,'Candidate Database'!U$4:U$998=$C$2),25),"""")"),"") | G30: =IFERROR(__xludf.DUMMYFUNCTION("IFERROR(INDEX(FILTER('Candidate Database'!P$4:P$998,'Candidate Database'!U$4:U$998=$C$2),25),"""")"),"") | J30: Ghostkitchens
A31: =IF(COUNTIF('Candidate Database'!U$4:U$998,$C$2)>=26,26,"") | B31: =IFERROR(__xludf.DUMMYFUNCTION("IFERROR(INDEX(FILTER('Candidate Database'!B$4:B$998,'Candidate Database'!U$4:U$998=$C$2),26),"""")"),"") | C31: =IFERROR(__xludf.DUMMYFUNCTION("IFERROR(INDEX(FILTER('Candidate Database'!E$4:E$998,'Candidate Database'!U$4:U$998=$C$2),26),"""")"),"") | D31: =IFERROR(__xludf.DUMMYFUNCTION("IFERROR(INDEX(FILTER('Candidate Database'!G$4:G$998,'Candidate Database'!U$4:U$998=$C$2),26),"""")"),"") | E31: =IFERROR(__xludf.DUMMYFUNCTION("IFERROR(INDEX(FILTER('Candidate Database'!H$4:H$998,'Candidate Database'!U$4:U$998=$C$2),26),"""")"),"") | F31: =IFERROR(__xludf.DUMMYFUNCTION("IFERROR(INDEX(FILTER('Candidate Database'!R$4:R$998,'Candidate Database'!U$4:U$998=$C$2),26),"""")"),"") | G31: =IFERROR(__xludf.DUMMYFUNCTION("IFERROR(INDEX(FILTER('Candidate Database'!P$4:P$998,'Candidate Database'!U$4:U$998=$C$2),26),"""")"),"") | J31: Gupta Brands
A32: =IF(COUNTIF('Candidate Database'!U$4:U$998,$C$2)>=27,27,"") | B32: =IFERROR(__xludf.DUMMYFUNCTION("IFERROR(INDEX(FILTER('Candidate Database'!B$4:B$998,'Candidate Database'!U$4:U$998=$C$2),27),"""")"),"") | C32: =IFERROR(__xludf.DUMMYFUNCTION("IFERROR(INDEX(FILTER('Candidate Database'!E$4:E$998,'Candidate Database'!U$4:U$998=$C$2),27),"""")"),"") | D32: =IFERROR(__xludf.DUMMYFUNCTION("IFERROR(INDEX(FILTER('Candidate Database'!G$4:G$998,'Candidate Database'!U$4:U$998=$C$2),27),"""")"),"") | E32: =IFERROR(__xludf.DUMMYFUNCTION("IFERROR(INDEX(FILTER('Candidate Database'!H$4:H$998,'Candidate Database'!U$4:U$998=$C$2),27),"""")"),"") | F32: =IFERROR(__xludf.DUMMYFUNCTION("IFERROR(INDEX(FILTER('Candidate Database'!R$4:R$998,'Candidate Database'!U$4:U$998=$C$2),27),"""")"),"") | G32: =IFERROR(__xludf.DUMMYFUNCTION("IFERROR(INDEX(FILTER('Candidate Database'!P$4:P$998,'Candidate Database'!U$4:U$998=$C$2),27),"""")"),"") | J32: Huddle and Score
A33: =IF(COUNTIF('Candidate Database'!U$4:U$998,$C$2)>=28,28,"") | B33: =IFERROR(__xludf.DUMMYFUNCTION("IFERROR(INDEX(FILTER('Candidate Database'!B$4:B$998,'Candidate Database'!U$4:U$998=$C$2),28),"""")"),"") | C33: =IFERROR(__xludf.DUMMYFUNCTION("IFERROR(INDEX(FILTER('Candidate Database'!E$4:E$998,'Candidate Database'!U$4:U$998=$C$2),28),"""")"),"") | D33: =IFERROR(__xludf.DUMMYFUNCTION("IFERROR(INDEX(FILTER('Candidate Database'!G$4:G$998,'Candidate Database'!U$4:U$998=$C$2),28),"""")"),"") | E33: =IFERROR(__xludf.DUMMYFUNCTION("IFERROR(INDEX(FILTER('Candidate Database'!H$4:H$998,'Candidate Database'!U$4:U$998=$C$2),28),"""")"),"") | F33: =IFERROR(__xludf.DUMMYFUNCTION("IFERROR(INDEX(FILTER('Candidate Database'!R$4:R$998,'Candidate Database'!U$4:U$998=$C$2),28),"""")"),"") | G33: =IFERROR(__xludf.DUMMYFUNCTION("IFERROR(INDEX(FILTER('Candidate Database'!P$4:P$998,'Candidate Database'!U$4:U$998=$C$2),28),"""")"),"") | J33: Hummingtree
A34: =IF(COUNTIF('Candidate Database'!U$4:U$998,$C$2)>=29,29,"") | B34: =IFERROR(__xludf.DUMMYFUNCTION("IFERROR(INDEX(FILTER('Candidate Database'!B$4:B$998,'Candidate Database'!U$4:U$998=$C$2),29),"""")"),"") | C34: =IFERROR(__xludf.DUMMYFUNCTION("IFERROR(INDEX(FILTER('Candidate Database'!E$4:E$998,'Candidate Database'!U$4:U$998=$C$2),29),"""")"),"") | D34: =IFERROR(__xludf.DUMMYFUNCTION("IFERROR(INDEX(FILTER('Candidate Database'!G$4:G$998,'Candidate Database'!U$4:U$998=$C$2),29),"""")"),"") | E34: =IFERROR(__xludf.DUMMYFUNCTION("IFERROR(INDEX(FILTER('Candidate Database'!H$4:H$998,'Candidate Database'!U$4:U$998=$C$2),29),"""")"),"") | F34: =IFERROR(__xludf.DUMMYFUNCTION("IFERROR(INDEX(FILTER('Candidate Database'!R$4:R$998,'Candidate Database'!U$4:U$998=$C$2),29),"""")"),"") | G34: =IFERROR(__xludf.DUMMYFUNCTION("IFERROR(INDEX(FILTER('Candidate Database'!P$4:P$998,'Candidate Database'!U$4:U$998=$C$2),29),"""")"),"") | J34: Hunger Inc
A35: =IF(COUNTIF('Candidate Database'!U$4:U$998,$C$2)>=30,30,"") | B35: =IFERROR(__xludf.DUMMYFUNCTION("IFERROR(INDEX(FILTER('Candidate Database'!B$4:B$998,'Candidate Database'!U$4:U$998=$C$2),30),"""")"),"") | C35: =IFERROR(__xludf.DUMMYFUNCTION("IFERROR(INDEX(FILTER('Candidate Database'!E$4:E$998,'Candidate Database'!U$4:U$998=$C$2),30),"""")"),"") | D35: =IFERROR(__xludf.DUMMYFUNCTION("IFERROR(INDEX(FILTER('Candidate Database'!G$4:G$998,'Candidate Database'!U$4:U$998=$C$2),30),"""")"),"") | E35: =IFERROR(__xludf.DUMMYFUNCTION("IFERROR(INDEX(FILTER('Candidate Database'!H$4:H$998,'Candidate Database'!U$4:U$998=$C$2),30),"""")"),"") | F35: =IFERROR(__xludf.DUMMYFUNCTION("IFERROR(INDEX(FILTER('Candidate Database'!R$4:R$998,'Candidate Database'!U$4:U$998=$C$2),30),"""")"),"") | G35: =IFERROR(__xludf.DUMMYFUNCTION("IFERROR(INDEX(FILTER('Candidate Database'!P$4:P$998,'Candidate Database'!U$4:U$998=$C$2),30),"""")"),"") | J35: Idoru
A36: =IF(COUNTIF('Candidate Database'!U$4:U$998,$C$2)>=31,31,"") | B36: =IFERROR(__xludf.DUMMYFUNCTION("IFERROR(INDEX(FILTER('Candidate Database'!B$4:B$998,'Candidate Database'!U$4:U$998=$C$2),31),"""")"),"") | C36: =IFERROR(__xludf.DUMMYFUNCTION("IFERROR(INDEX(FILTER('Candidate Database'!E$4:E$998,'Candidate Database'!U$4:U$998=$C$2),31),"""")"),"") | D36: =IFERROR(__xludf.DUMMYFUNCTION("IFERROR(INDEX(FILTER('Candidate Database'!G$4:G$998,'Candidate Database'!U$4:U$998=$C$2),31),"""")"),"") | E36: =IFERROR(__xludf.DUMMYFUNCTION("IFERROR(INDEX(FILTER('Candidate Database'!H$4:H$998,'Candidate Database'!U$4:U$998=$C$2),31),"""")"),"") | F36: =IFERROR(__xludf.DUMMYFUNCTION("IFERROR(INDEX(FILTER('Candidate Database'!R$4:R$998,'Candidate Database'!U$4:U$998=$C$2),31),"""")"),"") | G36: =IFERROR(__xludf.DUMMYFUNCTION("IFERROR(INDEX(FILTER('Candidate Database'!P$4:P$998,'Candidate Database'!U$4:U$998=$C$2),31),"""")"),"") | J36: Ikai
A37: =IF(COUNTIF('Candidate Database'!U$4:U$998,$C$2)>=32,32,"") | B37: =IFERROR(__xludf.DUMMYFUNCTION("IFERROR(INDEX(FILTER('Candidate Database'!B$4:B$998,'Candidate Database'!U$4:U$998=$C$2),32),"""")"),"") | C37: =IFERROR(__xludf.DUMMYFUNCTION("IFERROR(INDEX(FILTER('Candidate Database'!E$4:E$998,'Candidate Database'!U$4:U$998=$C$2),32),"""")"),"") | D37: =IFERROR(__xludf.DUMMYFUNCTION("IFERROR(INDEX(FILTER('Candidate Database'!G$4:G$998,'Candidate Database'!U$4:U$998=$C$2),32),"""")"),"") | E37: =IFERROR(__xludf.DUMMYFUNCTION("IFERROR(INDEX(FILTER('Candidate Database'!H$4:H$998,'Candidate Database'!U$4:U$998=$C$2),32),"""")"),"") | F37: =IFERROR(__xludf.DUMMYFUNCTION("IFERROR(INDEX(FILTER('Candidate Database'!R$4:R$998,'Candidate Database'!U$4:U$998=$C$2),32),"""")"),"") | G37: =IFERROR(__xludf.DUMMYFUNCTION("IFERROR(INDEX(FILTER('Candidate Database'!P$4:P$998,'Candidate Database'!U$4:U$998=$C$2),32),"""")"),"") | J37: Izumi
A38: =IF(COUNTIF('Candidate Database'!U$4:U$998,$C$2)>=33,33,"") | B38: =IFERROR(__xludf.DUMMYFUNCTION("IFERROR(INDEX(FILTER('Candidate Database'!B$4:B$998,'Candidate Database'!U$4:U$998=$C$2),33),"""")"),"") | C38: =IFERROR(__xludf.DUMMYFUNCTION("IFERROR(INDEX(FILTER('Candidate Database'!E$4:E$998,'Candidate Database'!U$4:U$998=$C$2),33),"""")"),"") | D38: =IFERROR(__xludf.DUMMYFUNCTION("IFERROR(INDEX(FILTER('Candidate Database'!G$4:G$998,'Candidate Database'!U$4:U$998=$C$2),33),"""")"),"") | E38: =IFERROR(__xludf.DUMMYFUNCTION("IFERROR(INDEX(FILTER('Candidate Database'!H$4:H$998,'Candidate Database'!U$4:U$998=$C$2),33),"""")"),"") | F38: =IFERROR(__xludf.DUMMYFUNCTION("IFERROR(INDEX(FILTER('Candidate Database'!R$4:R$998,'Candidate Database'!U$4:U$998=$C$2),33),"""")"),"") | G38: =IFERROR(__xludf.DUMMYFUNCTION("IFERROR(INDEX(FILTER('Candidate Database'!P$4:P$998,'Candidate Database'!U$4:U$998=$C$2),33),"""")"),"") | J38: Izumi - GOA
A39: =IF(COUNTIF('Candidate Database'!U$4:U$998,$C$2)>=34,34,"") | B39: =IFERROR(__xludf.DUMMYFUNCTION("IFERROR(INDEX(FILTER('Candidate Database'!B$4:B$998,'Candidate Database'!U$4:U$998=$C$2),34),"""")"),"") | C39: =IFERROR(__xludf.DUMMYFUNCTION("IFERROR(INDEX(FILTER('Candidate Database'!E$4:E$998,'Candidate Database'!U$4:U$998=$C$2),34),"""")"),"") | D39: =IFERROR(__xludf.DUMMYFUNCTION("IFERROR(INDEX(FILTER('Candidate Database'!G$4:G$998,'Candidate Database'!U$4:U$998=$C$2),34),"""")"),"") | E39: =IFERROR(__xludf.DUMMYFUNCTION("IFERROR(INDEX(FILTER('Candidate Database'!H$4:H$998,'Candidate Database'!U$4:U$998=$C$2),34),"""")"),"") | F39: =IFERROR(__xludf.DUMMYFUNCTION("IFERROR(INDEX(FILTER('Candidate Database'!R$4:R$998,'Candidate Database'!U$4:U$998=$C$2),34),"""")"),"") | G39: =IFERROR(__xludf.DUMMYFUNCTION("IFERROR(INDEX(FILTER('Candidate Database'!P$4:P$998,'Candidate Database'!U$4:U$998=$C$2),34),"""")"),"") | J39: Kaia
A40: =IF(COUNTIF('Candidate Database'!U$4:U$998,$C$2)>=35,35,"") | B40: =IFERROR(__xludf.DUMMYFUNCTION("IFERROR(INDEX(FILTER('Candidate Database'!B$4:B$998,'Candidate Database'!U$4:U$998=$C$2),35),"""")"),"") | C40: =IFERROR(__xludf.DUMMYFUNCTION("IFERROR(INDEX(FILTER('Candidate Database'!E$4:E$998,'Candidate Database'!U$4:U$998=$C$2),35),"""")"),"") | D40: =IFERROR(__xludf.DUMMYFUNCTION("IFERROR(INDEX(FILTER('Candidate Database'!G$4:G$998,'Candidate Database'!U$4:U$998=$C$2),35),"""")"),"") | E40: =IFERROR(__xludf.DUMMYFUNCTION("IFERROR(INDEX(FILTER('Candidate Database'!H$4:H$998,'Candidate Database'!U$4:U$998=$C$2),35),"""")"),"") | F40: =IFERROR(__xludf.DUMMYFUNCTION("IFERROR(INDEX(FILTER('Candidate Database'!R$4:R$998,'Candidate Database'!U$4:U$998=$C$2),35),"""")"),"") | G40: =IFERROR(__xludf.DUMMYFUNCTION("IFERROR(INDEX(FILTER('Candidate Database'!P$4:P$998,'Candidate Database'!U$4:U$998=$C$2),35),"""")"),"") | J40: Kohinoor Group
A41: =IF(COUNTIF('Candidate Database'!U$4:U$998,$C$2)>=36,36,"") | B41: =IFERROR(__xludf.DUMMYFUNCTION("IFERROR(INDEX(FILTER('Candidate Database'!B$4:B$998,'Candidate Database'!U$4:U$998=$C$2),36),"""")"),"") | C41: =IFERROR(__xludf.DUMMYFUNCTION("IFERROR(INDEX(FILTER('Candidate Database'!E$4:E$998,'Candidate Database'!U$4:U$998=$C$2),36),"""")"),"") | D41: =IFERROR(__xludf.DUMMYFUNCTION("IFERROR(INDEX(FILTER('Candidate Database'!G$4:G$998,'Candidate Database'!U$4:U$998=$C$2),36),"""")"),"") | E41: =IFERROR(__xludf.DUMMYFUNCTION("IFERROR(INDEX(FILTER('Candidate Database'!H$4:H$998,'Candidate Database'!U$4:U$998=$C$2),36),"""")"),"") | F41: =IFERROR(__xludf.DUMMYFUNCTION("IFERROR(INDEX(FILTER('Candidate Database'!R$4:R$998,'Candidate Database'!U$4:U$998=$C$2),36),"""")"),"") | G41: =IFERROR(__xludf.DUMMYFUNCTION("IFERROR(INDEX(FILTER('Candidate Database'!P$4:P$998,'Candidate Database'!U$4:U$998=$C$2),36),"""")"),"") | J41: La Loca Maria
...

Sheet Sheet1
A1: # | B1: Candidate Name | C1: Role | D1: Current Salary | E1: Expected Salary | F1: CV Link | G1: Binge Screening Remarks | H1: Status

Sheet Sheet2
A1: # | B1: Candidate Name | C1: Role | D1: Current Salary | E1: Expected Salary | F1: CV Link | G1: Binge Screening Remarks | H1: Status
A2: 1 | B2: Shreetej Kapdekar | C2: Asst Cafe Manager | D2: 50K | F2: Shreetej-Kapdekar-Resume-2025 (1).pdf | H2: Interview Pending
A3: 2 | B3: Vrushank Vernekar | C3: Assistant Outlet Manager | D3: 40K | F3: Vrushank CV digital .pdf
A4: 3 | B4: Kaif Shaikh | C4: Barback | D4: 25k | F4: KAIF SHAIKH CV (1).pdf
